[2024-10-30T15:54:37.700+0000] {local_task_job_runner.py:123} INFO - ::group::Pre task execution logs
[2024-10-30T15:54:37.753+0000] {taskinstance.py:2612} INFO - Dependencies all met for dep_context=non-requeueable deps ti=<TaskInstance: etl_update_stock_ferrimac.extract_data_sells_directory scheduled__2024-10-28T22:00:00+00:00 [queued]>
[2024-10-30T15:54:38.390+0000] {taskinstance.py:2612} INFO - Dependencies all met for dep_context=requeueable deps ti=<TaskInstance: etl_update_stock_ferrimac.extract_data_sells_directory scheduled__2024-10-28T22:00:00+00:00 [queued]>
[2024-10-30T15:54:38.392+0000] {taskinstance.py:2865} INFO - Starting attempt 2 of 2
[2024-10-30T15:54:38.437+0000] {taskinstance.py:2888} INFO - Executing <Task(PythonOperator): extract_data_sells_directory> on 2024-10-28 22:00:00+00:00
[2024-10-30T15:54:38.454+0000] {warnings.py:112} WARNING - /home/***/.local/lib/python3.12/site-packages/***/task/task_runner/standard_task_runner.py:70: DeprecationWarning: This process (pid=162) is multi-threaded, use of fork() may lead to deadlocks in the child.
  pid = os.fork()

[2024-10-30T15:54:38.464+0000] {standard_task_runner.py:72} INFO - Started process 169 to run task
[2024-10-30T15:54:38.469+0000] {standard_task_runner.py:104} INFO - Running: ['***', 'tasks', 'run', 'etl_update_stock_ferrimac', 'extract_data_sells_directory', 'scheduled__2024-10-28T22:00:00+00:00', '--job-id', '11', '--raw', '--subdir', 'DAGS_FOLDER/object_dag.py', '--cfg-path', '/tmp/tmp8xg3bi79']
[2024-10-30T15:54:38.476+0000] {standard_task_runner.py:105} INFO - Job 11: Subtask extract_data_sells_directory
[2024-10-30T15:54:38.631+0000] {task_command.py:467} INFO - Running <TaskInstance: etl_update_stock_ferrimac.extract_data_sells_directory scheduled__2024-10-28T22:00:00+00:00 [running]> on host 325f5d91bf4d
[2024-10-30T15:54:38.899+0000] {taskinstance.py:3131} INFO - Exporting env vars: AIRFLOW_CTX_DAG_OWNER='***' AIRFLOW_CTX_DAG_ID='etl_update_stock_ferrimac' AIRFLOW_CTX_TASK_ID='extract_data_sells_directory' AIRFLOW_CTX_EXECUTION_DATE='2024-10-28T22:00:00+00:00' AIRFLOW_CTX_TRY_NUMBER='2' AIRFLOW_CTX_DAG_RUN_ID='scheduled__2024-10-28T22:00:00+00:00'
[2024-10-30T15:54:38.901+0000] {taskinstance.py:731} INFO - ::endgroup::
[2024-10-30T15:54:38.983+0000] {taskinstance.py:3310} ERROR - Task failed with exception
Traceback (most recent call last):
  File "/home/airflow/.local/lib/python3.12/site-packages/airflow/models/taskinstance.py", line 767, in _execute_task
    result = _execute_callable(context=context, **execute_callable_kwargs)
             ^^^^^^^^^^^^^^^^^^^^^^^^^^^^^^^^^^^^^^^^^^^^^^^^^^^^^^^^^^^^^
  File "/home/airflow/.local/lib/python3.12/site-packages/airflow/models/taskinstance.py", line 733, in _execute_callable
    return ExecutionCallableRunner(
           ^^^^^^^^^^^^^^^^^^^^^^^^
  File "/home/airflow/.local/lib/python3.12/site-packages/airflow/utils/operator_helpers.py", line 252, in run
    return self.func(*args, **kwargs)
           ^^^^^^^^^^^^^^^^^^^^^^^^^^
  File "/home/airflow/.local/lib/python3.12/site-packages/airflow/models/baseoperator.py", line 406, in wrapper
    return func(self, *args, **kwargs)
           ^^^^^^^^^^^^^^^^^^^^^^^^^^^
  File "/home/airflow/.local/lib/python3.12/site-packages/airflow/operators/python.py", line 238, in execute
    return_value = self.execute_callable()
                   ^^^^^^^^^^^^^^^^^^^^^^^
  File "/home/airflow/.local/lib/python3.12/site-packages/airflow/operators/python.py", line 256, in execute_callable
    return runner.run(*self.op_args, **self.op_kwargs)
           ^^^^^^^^^^^^^^^^^^^^^^^^^^^^^^^^^^^^^^^^^^^
  File "/home/airflow/.local/lib/python3.12/site-packages/airflow/utils/operator_helpers.py", line 252, in run
    return self.func(*args, **kwargs)
           ^^^^^^^^^^^^^^^^^^^^^^^^^^
  File "/opt/airflow/functions_etl/extract_file_sells_to_stock.py", line 53, in extract_file_sells_to_stock
    shutil.copy(str(archivo_origen), str(archivo_destino))
  File "/usr/local/lib/python3.12/shutil.py", line 436, in copy
    copymode(src, dst, follow_symlinks=follow_symlinks)
  File "/usr/local/lib/python3.12/shutil.py", line 317, in copymode
    chmod_func(dst, stat.S_IMODE(st.st_mode))
PermissionError: [Errno 1] Operation not permitted: 'base_datos/inventario/ventas_unidades.xlsx'
[2024-10-30T15:54:39.016+0000] {taskinstance.py:1225} INFO - Marking task as FAILED. dag_id=etl_update_stock_ferrimac, task_id=extract_data_sells_directory, run_id=scheduled__2024-10-28T22:00:00+00:00, execution_date=20241028T220000, start_date=20241030T155437, end_date=20241030T155439
[2024-10-30T15:54:39.052+0000] {taskinstance.py:340} INFO - ::group::Post task execution logs
[2024-10-30T15:54:39.054+0000] {standard_task_runner.py:124} ERROR - Failed to execute job 11 for task extract_data_sells_directory ([Errno 1] Operation not permitted: 'base_datos/inventario/ventas_unidades.xlsx'; 169)
Traceback (most recent call last):
  File "/home/airflow/.local/lib/python3.12/site-packages/airflow/task/task_runner/standard_task_runner.py", line 117, in _start_by_fork
    ret = args.func(args, dag=self.dag)
          ^^^^^^^^^^^^^^^^^^^^^^^^^^^^^
  File "/home/airflow/.local/lib/python3.12/site-packages/airflow/cli/cli_config.py", line 49, in command
    return func(*args, **kwargs)
           ^^^^^^^^^^^^^^^^^^^^^
  File "/home/airflow/.local/lib/python3.12/site-packages/airflow/utils/cli.py", line 115, in wrapper
    return f(*args, **kwargs)
           ^^^^^^^^^^^^^^^^^^
  File "/home/airflow/.local/lib/python3.12/site-packages/airflow/cli/commands/task_command.py", line 483, in task_run
    task_return_code = _run_task_by_selected_method(args, _dag, ti)
                       ^^^^^^^^^^^^^^^^^^^^^^^^^^^^^^^^^^^^^^^^^^^^
  File "/home/airflow/.local/lib/python3.12/site-packages/airflow/cli/commands/task_command.py", line 256, in _run_task_by_selected_method
    return _run_raw_task(args, ti)
           ^^^^^^^^^^^^^^^^^^^^^^^
  File "/home/airflow/.local/lib/python3.12/site-packages/airflow/cli/commands/task_command.py", line 341, in _run_raw_task
    return ti._run_raw_task(
           ^^^^^^^^^^^^^^^^^
  File "/home/airflow/.local/lib/python3.12/site-packages/airflow/utils/session.py", line 97, in wrapper
    return func(*args, session=session, **kwargs)
           ^^^^^^^^^^^^^^^^^^^^^^^^^^^^^^^^^^^^^^
  File "/home/airflow/.local/lib/python3.12/site-packages/airflow/models/taskinstance.py", line 3004, in _run_raw_task
    return _run_raw_task(
           ^^^^^^^^^^^^^^
  File "/home/airflow/.local/lib/python3.12/site-packages/airflow/models/taskinstance.py", line 273, in _run_raw_task
    TaskInstance._execute_task_with_callbacks(
  File "/home/airflow/.local/lib/python3.12/site-packages/airflow/models/taskinstance.py", line 3158, in _execute_task_with_callbacks
    result = self._execute_task(context, task_orig)
             ^^^^^^^^^^^^^^^^^^^^^^^^^^^^^^^^^^^^^^
  File "/home/airflow/.local/lib/python3.12/site-packages/airflow/models/taskinstance.py", line 3182, in _execute_task
    return _execute_task(self, context, task_orig)
           ^^^^^^^^^^^^^^^^^^^^^^^^^^^^^^^^^^^^^^^
  File "/home/airflow/.local/lib/python3.12/site-packages/airflow/models/taskinstance.py", line 767, in _execute_task
    result = _execute_callable(context=context, **execute_callable_kwargs)
             ^^^^^^^^^^^^^^^^^^^^^^^^^^^^^^^^^^^^^^^^^^^^^^^^^^^^^^^^^^^^^
  File "/home/airflow/.local/lib/python3.12/site-packages/airflow/models/taskinstance.py", line 733, in _execute_callable
    return ExecutionCallableRunner(
           ^^^^^^^^^^^^^^^^^^^^^^^^
  File "/home/airflow/.local/lib/python3.12/site-packages/airflow/utils/operator_helpers.py", line 252, in run
    return self.func(*args, **kwargs)
           ^^^^^^^^^^^^^^^^^^^^^^^^^^
  File "/home/airflow/.local/lib/python3.12/site-packages/airflow/models/baseoperator.py", line 406, in wrapper
    return func(self, *args, **kwargs)
           ^^^^^^^^^^^^^^^^^^^^^^^^^^^
  File "/home/airflow/.local/lib/python3.12/site-packages/airflow/operators/python.py", line 238, in execute
    return_value = self.execute_callable()
                   ^^^^^^^^^^^^^^^^^^^^^^^
  File "/home/airflow/.local/lib/python3.12/site-packages/airflow/operators/python.py", line 256, in execute_callable
    return runner.run(*self.op_args, **self.op_kwargs)
           ^^^^^^^^^^^^^^^^^^^^^^^^^^^^^^^^^^^^^^^^^^^
  File "/home/airflow/.local/lib/python3.12/site-packages/airflow/utils/operator_helpers.py", line 252, in run
    return self.func(*args, **kwargs)
           ^^^^^^^^^^^^^^^^^^^^^^^^^^
  File "/opt/airflow/functions_etl/extract_file_sells_to_stock.py", line 53, in extract_file_sells_to_stock
    shutil.copy(str(archivo_origen), str(archivo_destino))
  File "/usr/local/lib/python3.12/shutil.py", line 436, in copy
    copymode(src, dst, follow_symlinks=follow_symlinks)
  File "/usr/local/lib/python3.12/shutil.py", line 317, in copymode
    chmod_func(dst, stat.S_IMODE(st.st_mode))
PermissionError: [Errno 1] Operation not permitted: 'base_datos/inventario/ventas_unidades.xlsx'
[2024-10-30T15:54:39.127+0000] {local_task_job_runner.py:266} INFO - Task exited with return code 1
[2024-10-30T15:54:39.191+0000] {taskinstance.py:3900} INFO - 0 downstream tasks scheduled from follow-on schedule check
[2024-10-30T15:54:39.201+0000] {local_task_job_runner.py:245} INFO - ::endgroup::
[2024-10-30T16:06:32.450+0000] {local_task_job_runner.py:123} INFO - ::group::Pre task execution logs
[2024-10-30T16:06:32.507+0000] {taskinstance.py:2612} INFO - Dependencies all met for dep_context=non-requeueable deps ti=<TaskInstance: etl_update_stock_ferrimac.extract_data_sells_directory scheduled__2024-10-28T22:00:00+00:00 [queued]>
[2024-10-30T16:06:32.539+0000] {taskinstance.py:2612} INFO - Dependencies all met for dep_context=requeueable deps ti=<TaskInstance: etl_update_stock_ferrimac.extract_data_sells_directory scheduled__2024-10-28T22:00:00+00:00 [queued]>
[2024-10-30T16:06:32.541+0000] {taskinstance.py:2865} INFO - Starting attempt 2 of 2
[2024-10-30T16:06:32.589+0000] {taskinstance.py:2888} INFO - Executing <Task(PythonOperator): extract_data_sells_directory> on 2024-10-28 22:00:00+00:00
[2024-10-30T16:06:32.605+0000] {warnings.py:112} WARNING - /home/***/.local/lib/python3.12/site-packages/***/task/task_runner/standard_task_runner.py:70: DeprecationWarning: This process (pid=73) is multi-threaded, use of fork() may lead to deadlocks in the child.
  pid = os.fork()

[2024-10-30T16:06:32.610+0000] {standard_task_runner.py:72} INFO - Started process 78 to run task
[2024-10-30T16:06:32.619+0000] {standard_task_runner.py:104} INFO - Running: ['***', 'tasks', 'run', 'etl_update_stock_ferrimac', 'extract_data_sells_directory', 'scheduled__2024-10-28T22:00:00+00:00', '--job-id', '11', '--raw', '--subdir', 'DAGS_FOLDER/object_dag.py', '--cfg-path', '/tmp/tmp9ltks8ug']
[2024-10-30T16:06:32.636+0000] {standard_task_runner.py:105} INFO - Job 11: Subtask extract_data_sells_directory
[2024-10-30T16:06:33.006+0000] {task_command.py:467} INFO - Running <TaskInstance: etl_update_stock_ferrimac.extract_data_sells_directory scheduled__2024-10-28T22:00:00+00:00 [running]> on host a17cb4a3e2ca
[2024-10-30T16:06:33.300+0000] {taskinstance.py:3131} INFO - Exporting env vars: AIRFLOW_CTX_DAG_OWNER='***' AIRFLOW_CTX_DAG_ID='etl_update_stock_ferrimac' AIRFLOW_CTX_TASK_ID='extract_data_sells_directory' AIRFLOW_CTX_EXECUTION_DATE='2024-10-28T22:00:00+00:00' AIRFLOW_CTX_TRY_NUMBER='2' AIRFLOW_CTX_DAG_RUN_ID='scheduled__2024-10-28T22:00:00+00:00'
[2024-10-30T16:06:33.303+0000] {taskinstance.py:731} INFO - ::endgroup::
[2024-10-30T16:06:33.451+0000] {taskinstance.py:3310} ERROR - Task failed with exception
Traceback (most recent call last):
  File "/home/airflow/.local/lib/python3.12/site-packages/airflow/models/taskinstance.py", line 767, in _execute_task
    result = _execute_callable(context=context, **execute_callable_kwargs)
             ^^^^^^^^^^^^^^^^^^^^^^^^^^^^^^^^^^^^^^^^^^^^^^^^^^^^^^^^^^^^^
  File "/home/airflow/.local/lib/python3.12/site-packages/airflow/models/taskinstance.py", line 733, in _execute_callable
    return ExecutionCallableRunner(
           ^^^^^^^^^^^^^^^^^^^^^^^^
  File "/home/airflow/.local/lib/python3.12/site-packages/airflow/utils/operator_helpers.py", line 252, in run
    return self.func(*args, **kwargs)
           ^^^^^^^^^^^^^^^^^^^^^^^^^^
  File "/home/airflow/.local/lib/python3.12/site-packages/airflow/models/baseoperator.py", line 406, in wrapper
    return func(self, *args, **kwargs)
           ^^^^^^^^^^^^^^^^^^^^^^^^^^^
  File "/home/airflow/.local/lib/python3.12/site-packages/airflow/operators/python.py", line 238, in execute
    return_value = self.execute_callable()
                   ^^^^^^^^^^^^^^^^^^^^^^^
  File "/home/airflow/.local/lib/python3.12/site-packages/airflow/operators/python.py", line 256, in execute_callable
    return runner.run(*self.op_args, **self.op_kwargs)
           ^^^^^^^^^^^^^^^^^^^^^^^^^^^^^^^^^^^^^^^^^^^
  File "/home/airflow/.local/lib/python3.12/site-packages/airflow/utils/operator_helpers.py", line 252, in run
    return self.func(*args, **kwargs)
           ^^^^^^^^^^^^^^^^^^^^^^^^^^
  File "/opt/airflow/functions_etl/extract_file_sells_to_stock.py", line 53, in extract_file_sells_to_stock
    shutil.copy(str(archivo_origen), str(archivo_destino))
  File "/usr/local/lib/python3.12/shutil.py", line 436, in copy
    copymode(src, dst, follow_symlinks=follow_symlinks)
  File "/usr/local/lib/python3.12/shutil.py", line 317, in copymode
    chmod_func(dst, stat.S_IMODE(st.st_mode))
PermissionError: [Errno 1] Operation not permitted: 'base_datos/inventario/ventas_unidades.xlsx'
[2024-10-30T16:06:33.498+0000] {taskinstance.py:1225} INFO - Marking task as FAILED. dag_id=etl_update_stock_ferrimac, task_id=extract_data_sells_directory, run_id=scheduled__2024-10-28T22:00:00+00:00, execution_date=20241028T220000, start_date=20241030T160632, end_date=20241030T160633
[2024-10-30T16:06:33.543+0000] {taskinstance.py:340} INFO - ::group::Post task execution logs
[2024-10-30T16:06:33.545+0000] {standard_task_runner.py:124} ERROR - Failed to execute job 11 for task extract_data_sells_directory ([Errno 1] Operation not permitted: 'base_datos/inventario/ventas_unidades.xlsx'; 78)
Traceback (most recent call last):
  File "/home/airflow/.local/lib/python3.12/site-packages/airflow/task/task_runner/standard_task_runner.py", line 117, in _start_by_fork
    ret = args.func(args, dag=self.dag)
          ^^^^^^^^^^^^^^^^^^^^^^^^^^^^^
  File "/home/airflow/.local/lib/python3.12/site-packages/airflow/cli/cli_config.py", line 49, in command
    return func(*args, **kwargs)
           ^^^^^^^^^^^^^^^^^^^^^
  File "/home/airflow/.local/lib/python3.12/site-packages/airflow/utils/cli.py", line 115, in wrapper
    return f(*args, **kwargs)
           ^^^^^^^^^^^^^^^^^^
  File "/home/airflow/.local/lib/python3.12/site-packages/airflow/cli/commands/task_command.py", line 483, in task_run
    task_return_code = _run_task_by_selected_method(args, _dag, ti)
                       ^^^^^^^^^^^^^^^^^^^^^^^^^^^^^^^^^^^^^^^^^^^^
  File "/home/airflow/.local/lib/python3.12/site-packages/airflow/cli/commands/task_command.py", line 256, in _run_task_by_selected_method
    return _run_raw_task(args, ti)
           ^^^^^^^^^^^^^^^^^^^^^^^
  File "/home/airflow/.local/lib/python3.12/site-packages/airflow/cli/commands/task_command.py", line 341, in _run_raw_task
    return ti._run_raw_task(
           ^^^^^^^^^^^^^^^^^
  File "/home/airflow/.local/lib/python3.12/site-packages/airflow/utils/session.py", line 97, in wrapper
    return func(*args, session=session, **kwargs)
           ^^^^^^^^^^^^^^^^^^^^^^^^^^^^^^^^^^^^^^
  File "/home/airflow/.local/lib/python3.12/site-packages/airflow/models/taskinstance.py", line 3004, in _run_raw_task
    return _run_raw_task(
           ^^^^^^^^^^^^^^
  File "/home/airflow/.local/lib/python3.12/site-packages/airflow/models/taskinstance.py", line 273, in _run_raw_task
    TaskInstance._execute_task_with_callbacks(
  File "/home/airflow/.local/lib/python3.12/site-packages/airflow/models/taskinstance.py", line 3158, in _execute_task_with_callbacks
    result = self._execute_task(context, task_orig)
             ^^^^^^^^^^^^^^^^^^^^^^^^^^^^^^^^^^^^^^
  File "/home/airflow/.local/lib/python3.12/site-packages/airflow/models/taskinstance.py", line 3182, in _execute_task
    return _execute_task(self, context, task_orig)
           ^^^^^^^^^^^^^^^^^^^^^^^^^^^^^^^^^^^^^^^
  File "/home/airflow/.local/lib/python3.12/site-packages/airflow/models/taskinstance.py", line 767, in _execute_task
    result = _execute_callable(context=context, **execute_callable_kwargs)
             ^^^^^^^^^^^^^^^^^^^^^^^^^^^^^^^^^^^^^^^^^^^^^^^^^^^^^^^^^^^^^
  File "/home/airflow/.local/lib/python3.12/site-packages/airflow/models/taskinstance.py", line 733, in _execute_callable
    return ExecutionCallableRunner(
           ^^^^^^^^^^^^^^^^^^^^^^^^
  File "/home/airflow/.local/lib/python3.12/site-packages/airflow/utils/operator_helpers.py", line 252, in run
    return self.func(*args, **kwargs)
           ^^^^^^^^^^^^^^^^^^^^^^^^^^
  File "/home/airflow/.local/lib/python3.12/site-packages/airflow/models/baseoperator.py", line 406, in wrapper
    return func(self, *args, **kwargs)
           ^^^^^^^^^^^^^^^^^^^^^^^^^^^
  File "/home/airflow/.local/lib/python3.12/site-packages/airflow/operators/python.py", line 238, in execute
    return_value = self.execute_callable()
                   ^^^^^^^^^^^^^^^^^^^^^^^
  File "/home/airflow/.local/lib/python3.12/site-packages/airflow/operators/python.py", line 256, in execute_callable
    return runner.run(*self.op_args, **self.op_kwargs)
           ^^^^^^^^^^^^^^^^^^^^^^^^^^^^^^^^^^^^^^^^^^^
  File "/home/airflow/.local/lib/python3.12/site-packages/airflow/utils/operator_helpers.py", line 252, in run
    return self.func(*args, **kwargs)
           ^^^^^^^^^^^^^^^^^^^^^^^^^^
  File "/opt/airflow/functions_etl/extract_file_sells_to_stock.py", line 53, in extract_file_sells_to_stock
    shutil.copy(str(archivo_origen), str(archivo_destino))
  File "/usr/local/lib/python3.12/shutil.py", line 436, in copy
    copymode(src, dst, follow_symlinks=follow_symlinks)
  File "/usr/local/lib/python3.12/shutil.py", line 317, in copymode
    chmod_func(dst, stat.S_IMODE(st.st_mode))
PermissionError: [Errno 1] Operation not permitted: 'base_datos/inventario/ventas_unidades.xlsx'
[2024-10-30T16:06:33.656+0000] {local_task_job_runner.py:266} INFO - Task exited with return code 1
[2024-10-30T16:06:33.781+0000] {taskinstance.py:3900} INFO - 0 downstream tasks scheduled from follow-on schedule check
[2024-10-30T16:06:33.818+0000] {local_task_job_runner.py:245} INFO - ::endgroup::
[2024-10-30T17:24:55.965+0000] {local_task_job_runner.py:123} INFO - ::group::Pre task execution logs
[2024-10-30T17:24:56.016+0000] {taskinstance.py:2612} INFO - Dependencies all met for dep_context=non-requeueable deps ti=<TaskInstance: etl_update_stock_ferrimac.extract_data_sells_directory scheduled__2024-10-28T22:00:00+00:00 [queued]>
[2024-10-30T17:24:56.048+0000] {taskinstance.py:2612} INFO - Dependencies all met for dep_context=requeueable deps ti=<TaskInstance: etl_update_stock_ferrimac.extract_data_sells_directory scheduled__2024-10-28T22:00:00+00:00 [queued]>
[2024-10-30T17:24:56.049+0000] {taskinstance.py:2865} INFO - Starting attempt 2 of 2
[2024-10-30T17:24:56.594+0000] {taskinstance.py:2888} INFO - Executing <Task(PythonOperator): extract_data_sells_directory> on 2024-10-28 22:00:00+00:00
[2024-10-30T17:24:56.611+0000] {warnings.py:112} WARNING - /home/***/.local/lib/python3.12/site-packages/***/task/task_runner/standard_task_runner.py:70: DeprecationWarning: This process (pid=188) is multi-threaded, use of fork() may lead to deadlocks in the child.
  pid = os.fork()

[2024-10-30T17:24:56.618+0000] {standard_task_runner.py:72} INFO - Started process 197 to run task
[2024-10-30T17:24:56.617+0000] {standard_task_runner.py:104} INFO - Running: ['***', 'tasks', 'run', 'etl_update_stock_ferrimac', 'extract_data_sells_directory', 'scheduled__2024-10-28T22:00:00+00:00', '--job-id', '10', '--raw', '--subdir', 'DAGS_FOLDER/object_dag.py', '--cfg-path', '/tmp/tmp_f6o5mwm']
[2024-10-30T17:24:56.630+0000] {standard_task_runner.py:105} INFO - Job 10: Subtask extract_data_sells_directory
[2024-10-30T17:24:56.812+0000] {task_command.py:467} INFO - Running <TaskInstance: etl_update_stock_ferrimac.extract_data_sells_directory scheduled__2024-10-28T22:00:00+00:00 [running]> on host ee74b327ac93
[2024-10-30T17:24:57.001+0000] {taskinstance.py:3131} INFO - Exporting env vars: AIRFLOW_CTX_DAG_OWNER='***' AIRFLOW_CTX_DAG_ID='etl_update_stock_ferrimac' AIRFLOW_CTX_TASK_ID='extract_data_sells_directory' AIRFLOW_CTX_EXECUTION_DATE='2024-10-28T22:00:00+00:00' AIRFLOW_CTX_TRY_NUMBER='2' AIRFLOW_CTX_DAG_RUN_ID='scheduled__2024-10-28T22:00:00+00:00'
[2024-10-30T17:24:57.003+0000] {taskinstance.py:731} INFO - ::endgroup::
[2024-10-30T17:24:57.077+0000] {taskinstance.py:3310} ERROR - Task failed with exception
Traceback (most recent call last):
  File "/home/airflow/.local/lib/python3.12/site-packages/airflow/models/taskinstance.py", line 767, in _execute_task
    result = _execute_callable(context=context, **execute_callable_kwargs)
             ^^^^^^^^^^^^^^^^^^^^^^^^^^^^^^^^^^^^^^^^^^^^^^^^^^^^^^^^^^^^^
  File "/home/airflow/.local/lib/python3.12/site-packages/airflow/models/taskinstance.py", line 733, in _execute_callable
    return ExecutionCallableRunner(
           ^^^^^^^^^^^^^^^^^^^^^^^^
  File "/home/airflow/.local/lib/python3.12/site-packages/airflow/utils/operator_helpers.py", line 252, in run
    return self.func(*args, **kwargs)
           ^^^^^^^^^^^^^^^^^^^^^^^^^^
  File "/home/airflow/.local/lib/python3.12/site-packages/airflow/models/baseoperator.py", line 406, in wrapper
    return func(self, *args, **kwargs)
           ^^^^^^^^^^^^^^^^^^^^^^^^^^^
  File "/home/airflow/.local/lib/python3.12/site-packages/airflow/operators/python.py", line 238, in execute
    return_value = self.execute_callable()
                   ^^^^^^^^^^^^^^^^^^^^^^^
  File "/home/airflow/.local/lib/python3.12/site-packages/airflow/operators/python.py", line 256, in execute_callable
    return runner.run(*self.op_args, **self.op_kwargs)
           ^^^^^^^^^^^^^^^^^^^^^^^^^^^^^^^^^^^^^^^^^^^
  File "/home/airflow/.local/lib/python3.12/site-packages/airflow/utils/operator_helpers.py", line 252, in run
    return self.func(*args, **kwargs)
           ^^^^^^^^^^^^^^^^^^^^^^^^^^
  File "/opt/airflow/functions_etl/extract_file_sells_to_stock.py", line 53, in extract_file_sells_to_stock
    shutil.copy(str(archivo_origen), str(archivo_destino))
  File "/usr/local/lib/python3.12/shutil.py", line 436, in copy
    copymode(src, dst, follow_symlinks=follow_symlinks)
  File "/usr/local/lib/python3.12/shutil.py", line 317, in copymode
    chmod_func(dst, stat.S_IMODE(st.st_mode))
PermissionError: [Errno 1] Operation not permitted: 'base_datos/inventario/ventas_unidades.xlsx'
[2024-10-30T17:24:57.111+0000] {taskinstance.py:1225} INFO - Marking task as FAILED. dag_id=etl_update_stock_ferrimac, task_id=extract_data_sells_directory, run_id=scheduled__2024-10-28T22:00:00+00:00, execution_date=20241028T220000, start_date=20241030T172456, end_date=20241030T172457
[2024-10-30T17:24:57.140+0000] {taskinstance.py:340} INFO - ::group::Post task execution logs
[2024-10-30T17:24:57.142+0000] {standard_task_runner.py:124} ERROR - Failed to execute job 10 for task extract_data_sells_directory ([Errno 1] Operation not permitted: 'base_datos/inventario/ventas_unidades.xlsx'; 197)
Traceback (most recent call last):
  File "/home/airflow/.local/lib/python3.12/site-packages/airflow/task/task_runner/standard_task_runner.py", line 117, in _start_by_fork
    ret = args.func(args, dag=self.dag)
          ^^^^^^^^^^^^^^^^^^^^^^^^^^^^^
  File "/home/airflow/.local/lib/python3.12/site-packages/airflow/cli/cli_config.py", line 49, in command
    return func(*args, **kwargs)
           ^^^^^^^^^^^^^^^^^^^^^
  File "/home/airflow/.local/lib/python3.12/site-packages/airflow/utils/cli.py", line 115, in wrapper
    return f(*args, **kwargs)
           ^^^^^^^^^^^^^^^^^^
  File "/home/airflow/.local/lib/python3.12/site-packages/airflow/cli/commands/task_command.py", line 483, in task_run
    task_return_code = _run_task_by_selected_method(args, _dag, ti)
                       ^^^^^^^^^^^^^^^^^^^^^^^^^^^^^^^^^^^^^^^^^^^^
  File "/home/airflow/.local/lib/python3.12/site-packages/airflow/cli/commands/task_command.py", line 256, in _run_task_by_selected_method
    return _run_raw_task(args, ti)
           ^^^^^^^^^^^^^^^^^^^^^^^
  File "/home/airflow/.local/lib/python3.12/site-packages/airflow/cli/commands/task_command.py", line 341, in _run_raw_task
    return ti._run_raw_task(
           ^^^^^^^^^^^^^^^^^
  File "/home/airflow/.local/lib/python3.12/site-packages/airflow/utils/session.py", line 97, in wrapper
    return func(*args, session=session, **kwargs)
           ^^^^^^^^^^^^^^^^^^^^^^^^^^^^^^^^^^^^^^
  File "/home/airflow/.local/lib/python3.12/site-packages/airflow/models/taskinstance.py", line 3004, in _run_raw_task
    return _run_raw_task(
           ^^^^^^^^^^^^^^
  File "/home/airflow/.local/lib/python3.12/site-packages/airflow/models/taskinstance.py", line 273, in _run_raw_task
    TaskInstance._execute_task_with_callbacks(
  File "/home/airflow/.local/lib/python3.12/site-packages/airflow/models/taskinstance.py", line 3158, in _execute_task_with_callbacks
    result = self._execute_task(context, task_orig)
             ^^^^^^^^^^^^^^^^^^^^^^^^^^^^^^^^^^^^^^
  File "/home/airflow/.local/lib/python3.12/site-packages/airflow/models/taskinstance.py", line 3182, in _execute_task
    return _execute_task(self, context, task_orig)
           ^^^^^^^^^^^^^^^^^^^^^^^^^^^^^^^^^^^^^^^
  File "/home/airflow/.local/lib/python3.12/site-packages/airflow/models/taskinstance.py", line 767, in _execute_task
    result = _execute_callable(context=context, **execute_callable_kwargs)
             ^^^^^^^^^^^^^^^^^^^^^^^^^^^^^^^^^^^^^^^^^^^^^^^^^^^^^^^^^^^^^
  File "/home/airflow/.local/lib/python3.12/site-packages/airflow/models/taskinstance.py", line 733, in _execute_callable
    return ExecutionCallableRunner(
           ^^^^^^^^^^^^^^^^^^^^^^^^
  File "/home/airflow/.local/lib/python3.12/site-packages/airflow/utils/operator_helpers.py", line 252, in run
    return self.func(*args, **kwargs)
           ^^^^^^^^^^^^^^^^^^^^^^^^^^
  File "/home/airflow/.local/lib/python3.12/site-packages/airflow/models/baseoperator.py", line 406, in wrapper
    return func(self, *args, **kwargs)
           ^^^^^^^^^^^^^^^^^^^^^^^^^^^
  File "/home/airflow/.local/lib/python3.12/site-packages/airflow/operators/python.py", line 238, in execute
    return_value = self.execute_callable()
                   ^^^^^^^^^^^^^^^^^^^^^^^
  File "/home/airflow/.local/lib/python3.12/site-packages/airflow/operators/python.py", line 256, in execute_callable
    return runner.run(*self.op_args, **self.op_kwargs)
           ^^^^^^^^^^^^^^^^^^^^^^^^^^^^^^^^^^^^^^^^^^^
  File "/home/airflow/.local/lib/python3.12/site-packages/airflow/utils/operator_helpers.py", line 252, in run
    return self.func(*args, **kwargs)
           ^^^^^^^^^^^^^^^^^^^^^^^^^^
  File "/opt/airflow/functions_etl/extract_file_sells_to_stock.py", line 53, in extract_file_sells_to_stock
    shutil.copy(str(archivo_origen), str(archivo_destino))
  File "/usr/local/lib/python3.12/shutil.py", line 436, in copy
    copymode(src, dst, follow_symlinks=follow_symlinks)
  File "/usr/local/lib/python3.12/shutil.py", line 317, in copymode
    chmod_func(dst, stat.S_IMODE(st.st_mode))
PermissionError: [Errno 1] Operation not permitted: 'base_datos/inventario/ventas_unidades.xlsx'
[2024-10-30T17:24:57.200+0000] {local_task_job_runner.py:266} INFO - Task exited with return code 1
[2024-10-30T17:24:57.291+0000] {taskinstance.py:3900} INFO - 0 downstream tasks scheduled from follow-on schedule check
[2024-10-30T17:24:57.343+0000] {local_task_job_runner.py:245} INFO - ::endgroup::
[2024-10-30T17:46:08.123+0000] {local_task_job_runner.py:123} INFO - ::group::Pre task execution logs
[2024-10-30T17:46:08.177+0000] {taskinstance.py:2612} INFO - Dependencies all met for dep_context=non-requeueable deps ti=<TaskInstance: etl_update_stock_ferrimac.extract_data_sells_directory scheduled__2024-10-28T22:00:00+00:00 [queued]>
[2024-10-30T17:46:08.205+0000] {taskinstance.py:2612} INFO - Dependencies all met for dep_context=requeueable deps ti=<TaskInstance: etl_update_stock_ferrimac.extract_data_sells_directory scheduled__2024-10-28T22:00:00+00:00 [queued]>
[2024-10-30T17:46:08.206+0000] {taskinstance.py:2865} INFO - Starting attempt 2 of 2
[2024-10-30T17:46:08.676+0000] {taskinstance.py:2888} INFO - Executing <Task(PythonOperator): extract_data_sells_directory> on 2024-10-28 22:00:00+00:00
[2024-10-30T17:46:08.692+0000] {warnings.py:112} WARNING - /home/***/.local/lib/python3.12/site-packages/***/task/task_runner/standard_task_runner.py:70: DeprecationWarning: This process (pid=193) is multi-threaded, use of fork() may lead to deadlocks in the child.
  pid = os.fork()

[2024-10-30T17:46:08.698+0000] {standard_task_runner.py:72} INFO - Started process 203 to run task
[2024-10-30T17:46:08.700+0000] {standard_task_runner.py:104} INFO - Running: ['***', 'tasks', 'run', 'etl_update_stock_ferrimac', 'extract_data_sells_directory', 'scheduled__2024-10-28T22:00:00+00:00', '--job-id', '10', '--raw', '--subdir', 'DAGS_FOLDER/object_dag.py', '--cfg-path', '/tmp/tmpvtkriteh']
[2024-10-30T17:46:08.710+0000] {standard_task_runner.py:105} INFO - Job 10: Subtask extract_data_sells_directory
[2024-10-30T17:46:08.879+0000] {task_command.py:467} INFO - Running <TaskInstance: etl_update_stock_ferrimac.extract_data_sells_directory scheduled__2024-10-28T22:00:00+00:00 [running]> on host 996bd14352fb
[2024-10-30T17:46:09.129+0000] {taskinstance.py:3131} INFO - Exporting env vars: AIRFLOW_CTX_DAG_OWNER='***' AIRFLOW_CTX_DAG_ID='etl_update_stock_ferrimac' AIRFLOW_CTX_TASK_ID='extract_data_sells_directory' AIRFLOW_CTX_EXECUTION_DATE='2024-10-28T22:00:00+00:00' AIRFLOW_CTX_TRY_NUMBER='2' AIRFLOW_CTX_DAG_RUN_ID='scheduled__2024-10-28T22:00:00+00:00'
[2024-10-30T17:46:09.132+0000] {taskinstance.py:731} INFO - ::endgroup::
[2024-10-30T17:46:09.228+0000] {taskinstance.py:3310} ERROR - Task failed with exception
Traceback (most recent call last):
  File "/home/airflow/.local/lib/python3.12/site-packages/airflow/models/taskinstance.py", line 767, in _execute_task
    result = _execute_callable(context=context, **execute_callable_kwargs)
             ^^^^^^^^^^^^^^^^^^^^^^^^^^^^^^^^^^^^^^^^^^^^^^^^^^^^^^^^^^^^^
  File "/home/airflow/.local/lib/python3.12/site-packages/airflow/models/taskinstance.py", line 733, in _execute_callable
    return ExecutionCallableRunner(
           ^^^^^^^^^^^^^^^^^^^^^^^^
  File "/home/airflow/.local/lib/python3.12/site-packages/airflow/utils/operator_helpers.py", line 252, in run
    return self.func(*args, **kwargs)
           ^^^^^^^^^^^^^^^^^^^^^^^^^^
  File "/home/airflow/.local/lib/python3.12/site-packages/airflow/models/baseoperator.py", line 406, in wrapper
    return func(self, *args, **kwargs)
           ^^^^^^^^^^^^^^^^^^^^^^^^^^^
  File "/home/airflow/.local/lib/python3.12/site-packages/airflow/operators/python.py", line 238, in execute
    return_value = self.execute_callable()
                   ^^^^^^^^^^^^^^^^^^^^^^^
  File "/home/airflow/.local/lib/python3.12/site-packages/airflow/operators/python.py", line 256, in execute_callable
    return runner.run(*self.op_args, **self.op_kwargs)
           ^^^^^^^^^^^^^^^^^^^^^^^^^^^^^^^^^^^^^^^^^^^
  File "/home/airflow/.local/lib/python3.12/site-packages/airflow/utils/operator_helpers.py", line 252, in run
    return self.func(*args, **kwargs)
           ^^^^^^^^^^^^^^^^^^^^^^^^^^
  File "/opt/airflow/functions_etl/extract_file_sells_to_stock.py", line 53, in extract_file_sells_to_stock
    shutil.copy(str(archivo_origen), str(archivo_destino))
  File "/usr/local/lib/python3.12/shutil.py", line 436, in copy
    copymode(src, dst, follow_symlinks=follow_symlinks)
  File "/usr/local/lib/python3.12/shutil.py", line 317, in copymode
    chmod_func(dst, stat.S_IMODE(st.st_mode))
PermissionError: [Errno 1] Operation not permitted: 'base_datos/inventario/ventas_unidades.xlsx'
[2024-10-30T17:46:09.275+0000] {taskinstance.py:1225} INFO - Marking task as FAILED. dag_id=etl_update_stock_ferrimac, task_id=extract_data_sells_directory, run_id=scheduled__2024-10-28T22:00:00+00:00, execution_date=20241028T220000, start_date=20241030T174608, end_date=20241030T174609
[2024-10-30T17:46:09.336+0000] {taskinstance.py:340} INFO - ::group::Post task execution logs
[2024-10-30T17:46:09.340+0000] {standard_task_runner.py:124} ERROR - Failed to execute job 10 for task extract_data_sells_directory ([Errno 1] Operation not permitted: 'base_datos/inventario/ventas_unidades.xlsx'; 203)
Traceback (most recent call last):
  File "/home/airflow/.local/lib/python3.12/site-packages/airflow/task/task_runner/standard_task_runner.py", line 117, in _start_by_fork
    ret = args.func(args, dag=self.dag)
          ^^^^^^^^^^^^^^^^^^^^^^^^^^^^^
  File "/home/airflow/.local/lib/python3.12/site-packages/airflow/cli/cli_config.py", line 49, in command
    return func(*args, **kwargs)
           ^^^^^^^^^^^^^^^^^^^^^
  File "/home/airflow/.local/lib/python3.12/site-packages/airflow/utils/cli.py", line 115, in wrapper
    return f(*args, **kwargs)
           ^^^^^^^^^^^^^^^^^^
  File "/home/airflow/.local/lib/python3.12/site-packages/airflow/cli/commands/task_command.py", line 483, in task_run
    task_return_code = _run_task_by_selected_method(args, _dag, ti)
                       ^^^^^^^^^^^^^^^^^^^^^^^^^^^^^^^^^^^^^^^^^^^^
  File "/home/airflow/.local/lib/python3.12/site-packages/airflow/cli/commands/task_command.py", line 256, in _run_task_by_selected_method
    return _run_raw_task(args, ti)
           ^^^^^^^^^^^^^^^^^^^^^^^
  File "/home/airflow/.local/lib/python3.12/site-packages/airflow/cli/commands/task_command.py", line 341, in _run_raw_task
    return ti._run_raw_task(
           ^^^^^^^^^^^^^^^^^
  File "/home/airflow/.local/lib/python3.12/site-packages/airflow/utils/session.py", line 97, in wrapper
    return func(*args, session=session, **kwargs)
           ^^^^^^^^^^^^^^^^^^^^^^^^^^^^^^^^^^^^^^
  File "/home/airflow/.local/lib/python3.12/site-packages/airflow/models/taskinstance.py", line 3004, in _run_raw_task
    return _run_raw_task(
           ^^^^^^^^^^^^^^
  File "/home/airflow/.local/lib/python3.12/site-packages/airflow/models/taskinstance.py", line 273, in _run_raw_task
    TaskInstance._execute_task_with_callbacks(
  File "/home/airflow/.local/lib/python3.12/site-packages/airflow/models/taskinstance.py", line 3158, in _execute_task_with_callbacks
    result = self._execute_task(context, task_orig)
             ^^^^^^^^^^^^^^^^^^^^^^^^^^^^^^^^^^^^^^
  File "/home/airflow/.local/lib/python3.12/site-packages/airflow/models/taskinstance.py", line 3182, in _execute_task
    return _execute_task(self, context, task_orig)
           ^^^^^^^^^^^^^^^^^^^^^^^^^^^^^^^^^^^^^^^
  File "/home/airflow/.local/lib/python3.12/site-packages/airflow/models/taskinstance.py", line 767, in _execute_task
    result = _execute_callable(context=context, **execute_callable_kwargs)
             ^^^^^^^^^^^^^^^^^^^^^^^^^^^^^^^^^^^^^^^^^^^^^^^^^^^^^^^^^^^^^
  File "/home/airflow/.local/lib/python3.12/site-packages/airflow/models/taskinstance.py", line 733, in _execute_callable
    return ExecutionCallableRunner(
           ^^^^^^^^^^^^^^^^^^^^^^^^
  File "/home/airflow/.local/lib/python3.12/site-packages/airflow/utils/operator_helpers.py", line 252, in run
    return self.func(*args, **kwargs)
           ^^^^^^^^^^^^^^^^^^^^^^^^^^
  File "/home/airflow/.local/lib/python3.12/site-packages/airflow/models/baseoperator.py", line 406, in wrapper
    return func(self, *args, **kwargs)
           ^^^^^^^^^^^^^^^^^^^^^^^^^^^
  File "/home/airflow/.local/lib/python3.12/site-packages/airflow/operators/python.py", line 238, in execute
    return_value = self.execute_callable()
                   ^^^^^^^^^^^^^^^^^^^^^^^
  File "/home/airflow/.local/lib/python3.12/site-packages/airflow/operators/python.py", line 256, in execute_callable
    return runner.run(*self.op_args, **self.op_kwargs)
           ^^^^^^^^^^^^^^^^^^^^^^^^^^^^^^^^^^^^^^^^^^^
  File "/home/airflow/.local/lib/python3.12/site-packages/airflow/utils/operator_helpers.py", line 252, in run
    return self.func(*args, **kwargs)
           ^^^^^^^^^^^^^^^^^^^^^^^^^^
  File "/opt/airflow/functions_etl/extract_file_sells_to_stock.py", line 53, in extract_file_sells_to_stock
    shutil.copy(str(archivo_origen), str(archivo_destino))
  File "/usr/local/lib/python3.12/shutil.py", line 436, in copy
    copymode(src, dst, follow_symlinks=follow_symlinks)
  File "/usr/local/lib/python3.12/shutil.py", line 317, in copymode
    chmod_func(dst, stat.S_IMODE(st.st_mode))
PermissionError: [Errno 1] Operation not permitted: 'base_datos/inventario/ventas_unidades.xlsx'
[2024-10-30T17:46:09.401+0000] {local_task_job_runner.py:266} INFO - Task exited with return code 1
[2024-10-30T17:46:09.445+0000] {local_task_job_runner.py:245} INFO - ::endgroup::
[2024-10-30T19:23:00.931+0000] {local_task_job_runner.py:123} INFO - ::group::Pre task execution logs
[2024-10-30T19:23:00.975+0000] {taskinstance.py:2612} INFO - Dependencies all met for dep_context=non-requeueable deps ti=<TaskInstance: etl_update_stock_ferrimac.extract_data_sells_directory scheduled__2024-10-28T22:00:00+00:00 [queued]>
[2024-10-30T19:23:01.030+0000] {taskinstance.py:2612} INFO - Dependencies all met for dep_context=requeueable deps ti=<TaskInstance: etl_update_stock_ferrimac.extract_data_sells_directory scheduled__2024-10-28T22:00:00+00:00 [queued]>
[2024-10-30T19:23:01.032+0000] {taskinstance.py:2865} INFO - Starting attempt 2 of 2
[2024-10-30T19:23:01.068+0000] {taskinstance.py:2888} INFO - Executing <Task(PythonOperator): extract_data_sells_directory> on 2024-10-28 22:00:00+00:00
[2024-10-30T19:23:01.082+0000] {warnings.py:112} WARNING - /home/***/.local/lib/python3.12/site-packages/***/task/task_runner/standard_task_runner.py:70: DeprecationWarning: This process (pid=189) is multi-threaded, use of fork() may lead to deadlocks in the child.
  pid = os.fork()

[2024-10-30T19:23:01.086+0000] {standard_task_runner.py:72} INFO - Started process 197 to run task
[2024-10-30T19:23:01.088+0000] {standard_task_runner.py:104} INFO - Running: ['***', 'tasks', 'run', 'etl_update_stock_ferrimac', 'extract_data_sells_directory', 'scheduled__2024-10-28T22:00:00+00:00', '--job-id', '10', '--raw', '--subdir', 'DAGS_FOLDER/object_dag.py', '--cfg-path', '/tmp/tmphvkzcetd']
[2024-10-30T19:23:01.094+0000] {standard_task_runner.py:105} INFO - Job 10: Subtask extract_data_sells_directory
[2024-10-30T19:23:01.239+0000] {task_command.py:467} INFO - Running <TaskInstance: etl_update_stock_ferrimac.extract_data_sells_directory scheduled__2024-10-28T22:00:00+00:00 [running]> on host 2b65cc0e065c
[2024-10-30T19:23:01.954+0000] {taskinstance.py:3131} INFO - Exporting env vars: AIRFLOW_CTX_DAG_OWNER='***' AIRFLOW_CTX_DAG_ID='etl_update_stock_ferrimac' AIRFLOW_CTX_TASK_ID='extract_data_sells_directory' AIRFLOW_CTX_EXECUTION_DATE='2024-10-28T22:00:00+00:00' AIRFLOW_CTX_TRY_NUMBER='2' AIRFLOW_CTX_DAG_RUN_ID='scheduled__2024-10-28T22:00:00+00:00'
[2024-10-30T19:23:01.957+0000] {taskinstance.py:731} INFO - ::endgroup::
[2024-10-30T19:23:02.051+0000] {taskinstance.py:3310} ERROR - Task failed with exception
Traceback (most recent call last):
  File "/home/airflow/.local/lib/python3.12/site-packages/airflow/models/taskinstance.py", line 767, in _execute_task
    result = _execute_callable(context=context, **execute_callable_kwargs)
             ^^^^^^^^^^^^^^^^^^^^^^^^^^^^^^^^^^^^^^^^^^^^^^^^^^^^^^^^^^^^^
  File "/home/airflow/.local/lib/python3.12/site-packages/airflow/models/taskinstance.py", line 733, in _execute_callable
    return ExecutionCallableRunner(
           ^^^^^^^^^^^^^^^^^^^^^^^^
  File "/home/airflow/.local/lib/python3.12/site-packages/airflow/utils/operator_helpers.py", line 252, in run
    return self.func(*args, **kwargs)
           ^^^^^^^^^^^^^^^^^^^^^^^^^^
  File "/home/airflow/.local/lib/python3.12/site-packages/airflow/models/baseoperator.py", line 406, in wrapper
    return func(self, *args, **kwargs)
           ^^^^^^^^^^^^^^^^^^^^^^^^^^^
  File "/home/airflow/.local/lib/python3.12/site-packages/airflow/operators/python.py", line 238, in execute
    return_value = self.execute_callable()
                   ^^^^^^^^^^^^^^^^^^^^^^^
  File "/home/airflow/.local/lib/python3.12/site-packages/airflow/operators/python.py", line 256, in execute_callable
    return runner.run(*self.op_args, **self.op_kwargs)
           ^^^^^^^^^^^^^^^^^^^^^^^^^^^^^^^^^^^^^^^^^^^
  File "/home/airflow/.local/lib/python3.12/site-packages/airflow/utils/operator_helpers.py", line 252, in run
    return self.func(*args, **kwargs)
           ^^^^^^^^^^^^^^^^^^^^^^^^^^
  File "/opt/airflow/functions_etl/extract_file_sells_to_stock.py", line 53, in extract_file_sells_to_stock
    shutil.copy(str(archivo_origen), str(archivo_destino))
  File "/usr/local/lib/python3.12/shutil.py", line 436, in copy
    copymode(src, dst, follow_symlinks=follow_symlinks)
  File "/usr/local/lib/python3.12/shutil.py", line 317, in copymode
    chmod_func(dst, stat.S_IMODE(st.st_mode))
PermissionError: [Errno 1] Operation not permitted: 'base_datos/inventario/ventas_unidades.csv'
[2024-10-30T19:23:02.087+0000] {taskinstance.py:1225} INFO - Marking task as FAILED. dag_id=etl_update_stock_ferrimac, task_id=extract_data_sells_directory, run_id=scheduled__2024-10-28T22:00:00+00:00, execution_date=20241028T220000, start_date=20241030T192300, end_date=20241030T192302
[2024-10-30T19:23:02.116+0000] {taskinstance.py:340} INFO - ::group::Post task execution logs
[2024-10-30T19:23:02.118+0000] {standard_task_runner.py:124} ERROR - Failed to execute job 10 for task extract_data_sells_directory ([Errno 1] Operation not permitted: 'base_datos/inventario/ventas_unidades.csv'; 197)
Traceback (most recent call last):
  File "/home/airflow/.local/lib/python3.12/site-packages/airflow/task/task_runner/standard_task_runner.py", line 117, in _start_by_fork
    ret = args.func(args, dag=self.dag)
          ^^^^^^^^^^^^^^^^^^^^^^^^^^^^^
  File "/home/airflow/.local/lib/python3.12/site-packages/airflow/cli/cli_config.py", line 49, in command
    return func(*args, **kwargs)
           ^^^^^^^^^^^^^^^^^^^^^
  File "/home/airflow/.local/lib/python3.12/site-packages/airflow/utils/cli.py", line 115, in wrapper
    return f(*args, **kwargs)
           ^^^^^^^^^^^^^^^^^^
  File "/home/airflow/.local/lib/python3.12/site-packages/airflow/cli/commands/task_command.py", line 483, in task_run
    task_return_code = _run_task_by_selected_method(args, _dag, ti)
                       ^^^^^^^^^^^^^^^^^^^^^^^^^^^^^^^^^^^^^^^^^^^^
  File "/home/airflow/.local/lib/python3.12/site-packages/airflow/cli/commands/task_command.py", line 256, in _run_task_by_selected_method
    return _run_raw_task(args, ti)
           ^^^^^^^^^^^^^^^^^^^^^^^
  File "/home/airflow/.local/lib/python3.12/site-packages/airflow/cli/commands/task_command.py", line 341, in _run_raw_task
    return ti._run_raw_task(
           ^^^^^^^^^^^^^^^^^
  File "/home/airflow/.local/lib/python3.12/site-packages/airflow/utils/session.py", line 97, in wrapper
    return func(*args, session=session, **kwargs)
           ^^^^^^^^^^^^^^^^^^^^^^^^^^^^^^^^^^^^^^
  File "/home/airflow/.local/lib/python3.12/site-packages/airflow/models/taskinstance.py", line 3004, in _run_raw_task
    return _run_raw_task(
           ^^^^^^^^^^^^^^
  File "/home/airflow/.local/lib/python3.12/site-packages/airflow/models/taskinstance.py", line 273, in _run_raw_task
    TaskInstance._execute_task_with_callbacks(
  File "/home/airflow/.local/lib/python3.12/site-packages/airflow/models/taskinstance.py", line 3158, in _execute_task_with_callbacks
    result = self._execute_task(context, task_orig)
             ^^^^^^^^^^^^^^^^^^^^^^^^^^^^^^^^^^^^^^
  File "/home/airflow/.local/lib/python3.12/site-packages/airflow/models/taskinstance.py", line 3182, in _execute_task
    return _execute_task(self, context, task_orig)
           ^^^^^^^^^^^^^^^^^^^^^^^^^^^^^^^^^^^^^^^
  File "/home/airflow/.local/lib/python3.12/site-packages/airflow/models/taskinstance.py", line 767, in _execute_task
    result = _execute_callable(context=context, **execute_callable_kwargs)
             ^^^^^^^^^^^^^^^^^^^^^^^^^^^^^^^^^^^^^^^^^^^^^^^^^^^^^^^^^^^^^
  File "/home/airflow/.local/lib/python3.12/site-packages/airflow/models/taskinstance.py", line 733, in _execute_callable
    return ExecutionCallableRunner(
           ^^^^^^^^^^^^^^^^^^^^^^^^
  File "/home/airflow/.local/lib/python3.12/site-packages/airflow/utils/operator_helpers.py", line 252, in run
    return self.func(*args, **kwargs)
           ^^^^^^^^^^^^^^^^^^^^^^^^^^
  File "/home/airflow/.local/lib/python3.12/site-packages/airflow/models/baseoperator.py", line 406, in wrapper
    return func(self, *args, **kwargs)
           ^^^^^^^^^^^^^^^^^^^^^^^^^^^
  File "/home/airflow/.local/lib/python3.12/site-packages/airflow/operators/python.py", line 238, in execute
    return_value = self.execute_callable()
                   ^^^^^^^^^^^^^^^^^^^^^^^
  File "/home/airflow/.local/lib/python3.12/site-packages/airflow/operators/python.py", line 256, in execute_callable
    return runner.run(*self.op_args, **self.op_kwargs)
           ^^^^^^^^^^^^^^^^^^^^^^^^^^^^^^^^^^^^^^^^^^^
  File "/home/airflow/.local/lib/python3.12/site-packages/airflow/utils/operator_helpers.py", line 252, in run
    return self.func(*args, **kwargs)
           ^^^^^^^^^^^^^^^^^^^^^^^^^^
  File "/opt/airflow/functions_etl/extract_file_sells_to_stock.py", line 53, in extract_file_sells_to_stock
    shutil.copy(str(archivo_origen), str(archivo_destino))
  File "/usr/local/lib/python3.12/shutil.py", line 436, in copy
    copymode(src, dst, follow_symlinks=follow_symlinks)
  File "/usr/local/lib/python3.12/shutil.py", line 317, in copymode
    chmod_func(dst, stat.S_IMODE(st.st_mode))
PermissionError: [Errno 1] Operation not permitted: 'base_datos/inventario/ventas_unidades.csv'
[2024-10-30T19:23:02.190+0000] {local_task_job_runner.py:266} INFO - Task exited with return code 1
[2024-10-30T19:23:02.212+0000] {local_task_job_runner.py:245} INFO - ::endgroup::
