[2024-10-15T00:00:01.642+0000] {local_task_job_runner.py:123} INFO - ::group::Pre task execution logs
[2024-10-15T00:00:01.697+0000] {taskinstance.py:2612} INFO - Dependencies all met for dep_context=non-requeueable deps ti=<TaskInstance: etl_update_stock_ferrimac.extract_data_sells_directory scheduled__2024-10-14T00:00:00+00:00 [queued]>
[2024-10-15T00:00:01.714+0000] {taskinstance.py:2612} INFO - Dependencies all met for dep_context=requeueable deps ti=<TaskInstance: etl_update_stock_ferrimac.extract_data_sells_directory scheduled__2024-10-14T00:00:00+00:00 [queued]>
[2024-10-15T00:00:01.715+0000] {taskinstance.py:2865} INFO - Starting attempt 1 of 2
[2024-10-15T00:00:02.036+0000] {taskinstance.py:2888} INFO - Executing <Task(PythonOperator): extract_data_sells_directory> on 2024-10-14 00:00:00+00:00
[2024-10-15T00:00:02.046+0000] {warnings.py:112} WARNING - /home/***/.local/lib/python3.12/site-packages/***/task/task_runner/standard_task_runner.py:70: DeprecationWarning: This process (pid=194) is multi-threaded, use of fork() may lead to deadlocks in the child.
  pid = os.fork()

[2024-10-15T00:00:02.049+0000] {standard_task_runner.py:72} INFO - Started process 204 to run task
[2024-10-15T00:00:02.048+0000] {standard_task_runner.py:104} INFO - Running: ['***', 'tasks', 'run', 'etl_update_stock_ferrimac', 'extract_data_sells_directory', 'scheduled__2024-10-14T00:00:00+00:00', '--job-id', '11', '--raw', '--subdir', 'DAGS_FOLDER/object_dag.py', '--cfg-path', '/tmp/tmpynfgja2s']
[2024-10-15T00:00:02.052+0000] {standard_task_runner.py:105} INFO - Job 11: Subtask extract_data_sells_directory
[2024-10-15T00:00:02.152+0000] {task_command.py:467} INFO - Running <TaskInstance: etl_update_stock_ferrimac.extract_data_sells_directory scheduled__2024-10-14T00:00:00+00:00 [running]> on host 038337c3b9ed
[2024-10-15T00:00:02.291+0000] {taskinstance.py:3131} INFO - Exporting env vars: AIRFLOW_CTX_DAG_OWNER='***' AIRFLOW_CTX_DAG_ID='etl_update_stock_ferrimac' AIRFLOW_CTX_TASK_ID='extract_data_sells_directory' AIRFLOW_CTX_EXECUTION_DATE='2024-10-14T00:00:00+00:00' AIRFLOW_CTX_TRY_NUMBER='1' AIRFLOW_CTX_DAG_RUN_ID='scheduled__2024-10-14T00:00:00+00:00'
[2024-10-15T00:00:02.293+0000] {taskinstance.py:731} INFO - ::endgroup::
[2024-10-15T00:00:02.322+0000] {logging_mixin.py:190} INFO - Directory base_datos/ventas not exist.
[2024-10-15T00:00:02.323+0000] {python.py:240} INFO - Done. Returned value was: None
[2024-10-15T00:00:02.339+0000] {taskinstance.py:340} INFO - ::group::Post task execution logs
[2024-10-15T00:00:02.340+0000] {taskinstance.py:352} INFO - Marking task as SUCCESS. dag_id=etl_update_stock_ferrimac, task_id=extract_data_sells_directory, run_id=scheduled__2024-10-14T00:00:00+00:00, execution_date=20241014T000000, start_date=20241015T000001, end_date=20241015T000002
[2024-10-15T00:00:02.388+0000] {local_task_job_runner.py:266} INFO - Task exited with return code 0
[2024-10-15T00:00:02.416+0000] {taskinstance.py:3900} INFO - 0 downstream tasks scheduled from follow-on schedule check
[2024-10-15T00:00:02.419+0000] {local_task_job_runner.py:245} INFO - ::endgroup::
[2024-10-15T04:44:44.831+0000] {local_task_job_runner.py:123} INFO - ::group::Pre task execution logs
[2024-10-15T04:44:44.865+0000] {taskinstance.py:2612} INFO - Dependencies all met for dep_context=non-requeueable deps ti=<TaskInstance: etl_update_stock_ferrimac.extract_data_sells_directory scheduled__2024-10-14T00:00:00+00:00 [queued]>
[2024-10-15T04:44:44.898+0000] {taskinstance.py:2612} INFO - Dependencies all met for dep_context=requeueable deps ti=<TaskInstance: etl_update_stock_ferrimac.extract_data_sells_directory scheduled__2024-10-14T00:00:00+00:00 [queued]>
[2024-10-15T04:44:44.903+0000] {taskinstance.py:2865} INFO - Starting attempt 1 of 2
[2024-10-15T04:44:44.935+0000] {taskinstance.py:2888} INFO - Executing <Task(PythonOperator): extract_data_sells_directory> on 2024-10-14 00:00:00+00:00
[2024-10-15T04:44:44.952+0000] {warnings.py:112} WARNING - /home/***/.local/lib/python3.12/site-packages/***/task/task_runner/standard_task_runner.py:70: DeprecationWarning: This process (pid=104) is multi-threaded, use of fork() may lead to deadlocks in the child.
  pid = os.fork()

[2024-10-15T04:44:44.956+0000] {standard_task_runner.py:72} INFO - Started process 113 to run task
[2024-10-15T04:44:44.953+0000] {standard_task_runner.py:104} INFO - Running: ['***', 'tasks', 'run', 'etl_update_stock_ferrimac', 'extract_data_sells_directory', 'scheduled__2024-10-14T00:00:00+00:00', '--job-id', '4', '--raw', '--subdir', 'DAGS_FOLDER/object_dag.py', '--cfg-path', '/tmp/tmpfcza1_jc']
[2024-10-15T04:44:44.959+0000] {standard_task_runner.py:105} INFO - Job 4: Subtask extract_data_sells_directory
[2024-10-15T04:44:45.059+0000] {task_command.py:467} INFO - Running <TaskInstance: etl_update_stock_ferrimac.extract_data_sells_directory scheduled__2024-10-14T00:00:00+00:00 [running]> on host 7ff0a1f24a3a
[2024-10-15T04:44:45.758+0000] {taskinstance.py:3131} INFO - Exporting env vars: AIRFLOW_CTX_DAG_OWNER='***' AIRFLOW_CTX_DAG_ID='etl_update_stock_ferrimac' AIRFLOW_CTX_TASK_ID='extract_data_sells_directory' AIRFLOW_CTX_EXECUTION_DATE='2024-10-14T00:00:00+00:00' AIRFLOW_CTX_TRY_NUMBER='1' AIRFLOW_CTX_DAG_RUN_ID='scheduled__2024-10-14T00:00:00+00:00'
[2024-10-15T04:44:45.760+0000] {taskinstance.py:731} INFO - ::endgroup::
[2024-10-15T04:44:45.926+0000] {taskinstance.py:3310} ERROR - Task failed with exception
Traceback (most recent call last):
  File "/home/airflow/.local/lib/python3.12/site-packages/airflow/models/taskinstance.py", line 767, in _execute_task
    result = _execute_callable(context=context, **execute_callable_kwargs)
             ^^^^^^^^^^^^^^^^^^^^^^^^^^^^^^^^^^^^^^^^^^^^^^^^^^^^^^^^^^^^^
  File "/home/airflow/.local/lib/python3.12/site-packages/airflow/models/taskinstance.py", line 733, in _execute_callable
    return ExecutionCallableRunner(
           ^^^^^^^^^^^^^^^^^^^^^^^^
  File "/home/airflow/.local/lib/python3.12/site-packages/airflow/utils/operator_helpers.py", line 252, in run
    return self.func(*args, **kwargs)
           ^^^^^^^^^^^^^^^^^^^^^^^^^^
  File "/home/airflow/.local/lib/python3.12/site-packages/airflow/models/baseoperator.py", line 406, in wrapper
    return func(self, *args, **kwargs)
           ^^^^^^^^^^^^^^^^^^^^^^^^^^^
  File "/home/airflow/.local/lib/python3.12/site-packages/airflow/operators/python.py", line 238, in execute
    return_value = self.execute_callable()
                   ^^^^^^^^^^^^^^^^^^^^^^^
  File "/home/airflow/.local/lib/python3.12/site-packages/airflow/operators/python.py", line 256, in execute_callable
    return runner.run(*self.op_args, **self.op_kwargs)
           ^^^^^^^^^^^^^^^^^^^^^^^^^^^^^^^^^^^^^^^^^^^
  File "/home/airflow/.local/lib/python3.12/site-packages/airflow/utils/operator_helpers.py", line 252, in run
    return self.func(*args, **kwargs)
           ^^^^^^^^^^^^^^^^^^^^^^^^^^
  File "/opt/airflow/functions_etl/extract_file_sells_to_stock.py", line 34, in extract_file_sells_to_stock
    shutil.copy(str(archivo_origen), str(archivo_destino))
  File "/usr/local/lib/python3.12/shutil.py", line 436, in copy
    copymode(src, dst, follow_symlinks=follow_symlinks)
  File "/usr/local/lib/python3.12/shutil.py", line 317, in copymode
    chmod_func(dst, stat.S_IMODE(st.st_mode))
PermissionError: [Errno 1] Operation not permitted: 'base_datos/inventario/ventas_unidades.xlsx'
[2024-10-15T04:44:45.954+0000] {taskinstance.py:1225} INFO - Marking task as UP_FOR_RETRY. dag_id=etl_update_stock_ferrimac, task_id=extract_data_sells_directory, run_id=scheduled__2024-10-14T00:00:00+00:00, execution_date=20241014T000000, start_date=20241015T044444, end_date=20241015T044445
[2024-10-15T04:44:45.976+0000] {taskinstance.py:340} INFO - ::group::Post task execution logs
[2024-10-15T04:44:45.977+0000] {standard_task_runner.py:124} ERROR - Failed to execute job 4 for task extract_data_sells_directory ([Errno 1] Operation not permitted: 'base_datos/inventario/ventas_unidades.xlsx'; 113)
Traceback (most recent call last):
  File "/home/airflow/.local/lib/python3.12/site-packages/airflow/task/task_runner/standard_task_runner.py", line 117, in _start_by_fork
    ret = args.func(args, dag=self.dag)
          ^^^^^^^^^^^^^^^^^^^^^^^^^^^^^
  File "/home/airflow/.local/lib/python3.12/site-packages/airflow/cli/cli_config.py", line 49, in command
    return func(*args, **kwargs)
           ^^^^^^^^^^^^^^^^^^^^^
  File "/home/airflow/.local/lib/python3.12/site-packages/airflow/utils/cli.py", line 115, in wrapper
    return f(*args, **kwargs)
           ^^^^^^^^^^^^^^^^^^
  File "/home/airflow/.local/lib/python3.12/site-packages/airflow/cli/commands/task_command.py", line 483, in task_run
    task_return_code = _run_task_by_selected_method(args, _dag, ti)
                       ^^^^^^^^^^^^^^^^^^^^^^^^^^^^^^^^^^^^^^^^^^^^
  File "/home/airflow/.local/lib/python3.12/site-packages/airflow/cli/commands/task_command.py", line 256, in _run_task_by_selected_method
    return _run_raw_task(args, ti)
           ^^^^^^^^^^^^^^^^^^^^^^^
  File "/home/airflow/.local/lib/python3.12/site-packages/airflow/cli/commands/task_command.py", line 341, in _run_raw_task
    return ti._run_raw_task(
           ^^^^^^^^^^^^^^^^^
  File "/home/airflow/.local/lib/python3.12/site-packages/airflow/utils/session.py", line 97, in wrapper
    return func(*args, session=session, **kwargs)
           ^^^^^^^^^^^^^^^^^^^^^^^^^^^^^^^^^^^^^^
  File "/home/airflow/.local/lib/python3.12/site-packages/airflow/models/taskinstance.py", line 3004, in _run_raw_task
    return _run_raw_task(
           ^^^^^^^^^^^^^^
  File "/home/airflow/.local/lib/python3.12/site-packages/airflow/models/taskinstance.py", line 273, in _run_raw_task
    TaskInstance._execute_task_with_callbacks(
  File "/home/airflow/.local/lib/python3.12/site-packages/airflow/models/taskinstance.py", line 3158, in _execute_task_with_callbacks
    result = self._execute_task(context, task_orig)
             ^^^^^^^^^^^^^^^^^^^^^^^^^^^^^^^^^^^^^^
  File "/home/airflow/.local/lib/python3.12/site-packages/airflow/models/taskinstance.py", line 3182, in _execute_task
    return _execute_task(self, context, task_orig)
           ^^^^^^^^^^^^^^^^^^^^^^^^^^^^^^^^^^^^^^^
  File "/home/airflow/.local/lib/python3.12/site-packages/airflow/models/taskinstance.py", line 767, in _execute_task
    result = _execute_callable(context=context, **execute_callable_kwargs)
             ^^^^^^^^^^^^^^^^^^^^^^^^^^^^^^^^^^^^^^^^^^^^^^^^^^^^^^^^^^^^^
  File "/home/airflow/.local/lib/python3.12/site-packages/airflow/models/taskinstance.py", line 733, in _execute_callable
    return ExecutionCallableRunner(
           ^^^^^^^^^^^^^^^^^^^^^^^^
  File "/home/airflow/.local/lib/python3.12/site-packages/airflow/utils/operator_helpers.py", line 252, in run
    return self.func(*args, **kwargs)
           ^^^^^^^^^^^^^^^^^^^^^^^^^^
  File "/home/airflow/.local/lib/python3.12/site-packages/airflow/models/baseoperator.py", line 406, in wrapper
    return func(self, *args, **kwargs)
           ^^^^^^^^^^^^^^^^^^^^^^^^^^^
  File "/home/airflow/.local/lib/python3.12/site-packages/airflow/operators/python.py", line 238, in execute
    return_value = self.execute_callable()
                   ^^^^^^^^^^^^^^^^^^^^^^^
  File "/home/airflow/.local/lib/python3.12/site-packages/airflow/operators/python.py", line 256, in execute_callable
    return runner.run(*self.op_args, **self.op_kwargs)
           ^^^^^^^^^^^^^^^^^^^^^^^^^^^^^^^^^^^^^^^^^^^
  File "/home/airflow/.local/lib/python3.12/site-packages/airflow/utils/operator_helpers.py", line 252, in run
    return self.func(*args, **kwargs)
           ^^^^^^^^^^^^^^^^^^^^^^^^^^
  File "/opt/airflow/functions_etl/extract_file_sells_to_stock.py", line 34, in extract_file_sells_to_stock
    shutil.copy(str(archivo_origen), str(archivo_destino))
  File "/usr/local/lib/python3.12/shutil.py", line 436, in copy
    copymode(src, dst, follow_symlinks=follow_symlinks)
  File "/usr/local/lib/python3.12/shutil.py", line 317, in copymode
    chmod_func(dst, stat.S_IMODE(st.st_mode))
PermissionError: [Errno 1] Operation not permitted: 'base_datos/inventario/ventas_unidades.xlsx'
[2024-10-15T04:44:46.021+0000] {local_task_job_runner.py:266} INFO - Task exited with return code 1
[2024-10-15T04:44:46.047+0000] {taskinstance.py:3900} INFO - 0 downstream tasks scheduled from follow-on schedule check
[2024-10-15T04:44:46.051+0000] {local_task_job_runner.py:245} INFO - ::endgroup::
[2024-10-15T14:05:58.913+0000] {local_task_job_runner.py:123} INFO - ::group::Pre task execution logs
[2024-10-15T14:05:59.312+0000] {taskinstance.py:2602} INFO - Dependencies not met for <TaskInstance: etl_update_stock_ferrimac.extract_data_sells_directory scheduled__2024-10-14T00:00:00+00:00 [up_for_retry]>, dependency 'Not In Retry Period' FAILED: Task is not ready for retry yet but will be retried automatically. Current date is 2024-10-15T14:05:59.308456+00:00 and task will be retried at 2024-10-15T14:10:38.334392+00:00.
[2024-10-15T14:05:59.349+0000] {local_task_job_runner.py:166} INFO - Task is not able to be run
