[2024-10-30T11:59:36.631+0000] {local_task_job_runner.py:123} INFO - ::group::Pre task execution logs
[2024-10-30T11:59:36.730+0000] {taskinstance.py:2612} INFO - Dependencies all met for dep_context=non-requeueable deps ti=<TaskInstance: etl_update_stock_ferrimac.load_data_into_Redshif scheduled__2024-10-28T22:00:00+00:00 [queued]>
[2024-10-30T11:59:36.756+0000] {taskinstance.py:2612} INFO - Dependencies all met for dep_context=requeueable deps ti=<TaskInstance: etl_update_stock_ferrimac.load_data_into_Redshif scheduled__2024-10-28T22:00:00+00:00 [queued]>
[2024-10-30T11:59:36.758+0000] {taskinstance.py:2865} INFO - Starting attempt 1 of 2
[2024-10-30T11:59:36.820+0000] {taskinstance.py:2888} INFO - Executing <Task(PythonOperator): load_data_into_Redshif> on 2024-10-28 22:00:00+00:00
[2024-10-30T11:59:36.835+0000] {warnings.py:112} WARNING - /home/***/.local/lib/python3.12/site-packages/***/task/task_runner/standard_task_runner.py:70: DeprecationWarning: This process (pid=182) is multi-threaded, use of fork() may lead to deadlocks in the child.
  pid = os.fork()

[2024-10-30T11:59:36.844+0000] {standard_task_runner.py:72} INFO - Started process 187 to run task
[2024-10-30T11:59:36.845+0000] {standard_task_runner.py:104} INFO - Running: ['***', 'tasks', 'run', 'etl_update_stock_ferrimac', 'load_data_into_Redshif', 'scheduled__2024-10-28T22:00:00+00:00', '--job-id', '14', '--raw', '--subdir', 'DAGS_FOLDER/object_dag.py', '--cfg-path', '/tmp/tmpenqwm2cn']
[2024-10-30T11:59:36.854+0000] {standard_task_runner.py:105} INFO - Job 14: Subtask load_data_into_Redshif
[2024-10-30T11:59:36.985+0000] {task_command.py:467} INFO - Running <TaskInstance: etl_update_stock_ferrimac.load_data_into_Redshif scheduled__2024-10-28T22:00:00+00:00 [running]> on host 0d5052666bc5
[2024-10-30T11:59:37.240+0000] {taskinstance.py:3131} INFO - Exporting env vars: AIRFLOW_CTX_DAG_OWNER='***' AIRFLOW_CTX_DAG_ID='etl_update_stock_ferrimac' AIRFLOW_CTX_TASK_ID='load_data_into_Redshif' AIRFLOW_CTX_EXECUTION_DATE='2024-10-28T22:00:00+00:00' AIRFLOW_CTX_TRY_NUMBER='1' AIRFLOW_CTX_DAG_RUN_ID='scheduled__2024-10-28T22:00:00+00:00'
[2024-10-30T11:59:37.244+0000] {taskinstance.py:731} INFO - ::endgroup::
[2024-10-30T11:59:40.581+0000] {load_data.py:116} INFO - Connection to Redshift successful.
[2024-10-30T11:59:40.908+0000] {load_data.py:119} INFO - Update from Redshift: 2024-10-30
[2024-10-30T11:59:41.396+0000] {taskinstance.py:3310} ERROR - Task failed with exception
Traceback (most recent call last):
  File "/opt/airflow/functions_etl/load_data.py", line 54, in load_data
    df = pd.read_excel(file_path, engine='openpyxl')
         ^^^^^^^^^^^^^^^^^^^^^^^^^^^^^^^^^^^^^^^^^^^
  File "/home/airflow/.local/lib/python3.12/site-packages/pandas/io/excel/_base.py", line 504, in read_excel
    io = ExcelFile(
         ^^^^^^^^^^
  File "/home/airflow/.local/lib/python3.12/site-packages/pandas/io/excel/_base.py", line 1580, in __init__
    self._reader = self._engines[engine](
                   ^^^^^^^^^^^^^^^^^^^^^^
  File "/home/airflow/.local/lib/python3.12/site-packages/pandas/io/excel/_openpyxl.py", line 553, in __init__
    super().__init__(
  File "/home/airflow/.local/lib/python3.12/site-packages/pandas/io/excel/_base.py", line 582, in __init__
    self.book = self.load_workbook(self.handles.handle, engine_kwargs)
                ^^^^^^^^^^^^^^^^^^^^^^^^^^^^^^^^^^^^^^^^^^^^^^^^^^^^^^
  File "/home/airflow/.local/lib/python3.12/site-packages/pandas/io/excel/_openpyxl.py", line 570, in load_workbook
    return load_workbook(
           ^^^^^^^^^^^^^^
  File "/home/airflow/.local/lib/python3.12/site-packages/openpyxl/reader/excel.py", line 315, in load_workbook
    reader = ExcelReader(filename, read_only, keep_vba,
             ^^^^^^^^^^^^^^^^^^^^^^^^^^^^^^^^^^^^^^^^^^
  File "/home/airflow/.local/lib/python3.12/site-packages/openpyxl/reader/excel.py", line 124, in __init__
    self.archive = _validate_archive(fn)
                   ^^^^^^^^^^^^^^^^^^^^^
  File "/home/airflow/.local/lib/python3.12/site-packages/openpyxl/reader/excel.py", line 96, in _validate_archive
    archive = ZipFile(filename, 'r')
              ^^^^^^^^^^^^^^^^^^^^^^
  File "/usr/local/lib/python3.12/zipfile/__init__.py", line 1349, in __init__
    self._RealGetContents()
  File "/usr/local/lib/python3.12/zipfile/__init__.py", line 1446, in _RealGetContents
    raise BadZipFile("Bad magic number for central directory")
zipfile.BadZipFile: Bad magic number for central directory

During handling of the above exception, another exception occurred:

Traceback (most recent call last):
  File "/home/airflow/.local/lib/python3.12/site-packages/airflow/models/taskinstance.py", line 767, in _execute_task
    result = _execute_callable(context=context, **execute_callable_kwargs)
             ^^^^^^^^^^^^^^^^^^^^^^^^^^^^^^^^^^^^^^^^^^^^^^^^^^^^^^^^^^^^^
  File "/home/airflow/.local/lib/python3.12/site-packages/airflow/models/taskinstance.py", line 733, in _execute_callable
    return ExecutionCallableRunner(
           ^^^^^^^^^^^^^^^^^^^^^^^^
  File "/home/airflow/.local/lib/python3.12/site-packages/airflow/utils/operator_helpers.py", line 252, in run
    return self.func(*args, **kwargs)
           ^^^^^^^^^^^^^^^^^^^^^^^^^^
  File "/home/airflow/.local/lib/python3.12/site-packages/airflow/models/baseoperator.py", line 406, in wrapper
    return func(self, *args, **kwargs)
           ^^^^^^^^^^^^^^^^^^^^^^^^^^^
  File "/home/airflow/.local/lib/python3.12/site-packages/airflow/operators/python.py", line 238, in execute
    return_value = self.execute_callable()
                   ^^^^^^^^^^^^^^^^^^^^^^^
  File "/home/airflow/.local/lib/python3.12/site-packages/airflow/operators/python.py", line 256, in execute_callable
    return runner.run(*self.op_args, **self.op_kwargs)
           ^^^^^^^^^^^^^^^^^^^^^^^^^^^^^^^^^^^^^^^^^^^
  File "/home/airflow/.local/lib/python3.12/site-packages/airflow/utils/operator_helpers.py", line 252, in run
    return self.func(*args, **kwargs)
           ^^^^^^^^^^^^^^^^^^^^^^^^^^
  File "/opt/airflow/functions_etl/load_data.py", line 124, in load_data_to_Redshift
    df = load_data(file)  # Ensure load_data has error handling
         ^^^^^^^^^^^^^^^
  File "/opt/airflow/functions_etl/load_data.py", line 68, in load_data
    raise RuntimeError(f"Error reading file: {e}")
RuntimeError: Error reading file: Bad magic number for central directory
[2024-10-30T11:59:41.442+0000] {taskinstance.py:1225} INFO - Marking task as UP_FOR_RETRY. dag_id=etl_update_stock_ferrimac, task_id=load_data_into_Redshif, run_id=scheduled__2024-10-28T22:00:00+00:00, execution_date=20241028T220000, start_date=20241030T115936, end_date=20241030T115941
[2024-10-30T11:59:41.489+0000] {taskinstance.py:340} INFO - ::group::Post task execution logs
[2024-10-30T11:59:41.493+0000] {standard_task_runner.py:124} ERROR - Failed to execute job 14 for task load_data_into_Redshif (Error reading file: Bad magic number for central directory; 187)
Traceback (most recent call last):
  File "/opt/airflow/functions_etl/load_data.py", line 54, in load_data
    df = pd.read_excel(file_path, engine='openpyxl')
         ^^^^^^^^^^^^^^^^^^^^^^^^^^^^^^^^^^^^^^^^^^^
  File "/home/airflow/.local/lib/python3.12/site-packages/pandas/io/excel/_base.py", line 504, in read_excel
    io = ExcelFile(
         ^^^^^^^^^^
  File "/home/airflow/.local/lib/python3.12/site-packages/pandas/io/excel/_base.py", line 1580, in __init__
    self._reader = self._engines[engine](
                   ^^^^^^^^^^^^^^^^^^^^^^
  File "/home/airflow/.local/lib/python3.12/site-packages/pandas/io/excel/_openpyxl.py", line 553, in __init__
    super().__init__(
  File "/home/airflow/.local/lib/python3.12/site-packages/pandas/io/excel/_base.py", line 582, in __init__
    self.book = self.load_workbook(self.handles.handle, engine_kwargs)
                ^^^^^^^^^^^^^^^^^^^^^^^^^^^^^^^^^^^^^^^^^^^^^^^^^^^^^^
  File "/home/airflow/.local/lib/python3.12/site-packages/pandas/io/excel/_openpyxl.py", line 570, in load_workbook
    return load_workbook(
           ^^^^^^^^^^^^^^
  File "/home/airflow/.local/lib/python3.12/site-packages/openpyxl/reader/excel.py", line 315, in load_workbook
    reader = ExcelReader(filename, read_only, keep_vba,
             ^^^^^^^^^^^^^^^^^^^^^^^^^^^^^^^^^^^^^^^^^^
  File "/home/airflow/.local/lib/python3.12/site-packages/openpyxl/reader/excel.py", line 124, in __init__
    self.archive = _validate_archive(fn)
                   ^^^^^^^^^^^^^^^^^^^^^
  File "/home/airflow/.local/lib/python3.12/site-packages/openpyxl/reader/excel.py", line 96, in _validate_archive
    archive = ZipFile(filename, 'r')
              ^^^^^^^^^^^^^^^^^^^^^^
  File "/usr/local/lib/python3.12/zipfile/__init__.py", line 1349, in __init__
    self._RealGetContents()
  File "/usr/local/lib/python3.12/zipfile/__init__.py", line 1446, in _RealGetContents
    raise BadZipFile("Bad magic number for central directory")
zipfile.BadZipFile: Bad magic number for central directory

During handling of the above exception, another exception occurred:

Traceback (most recent call last):
  File "/home/airflow/.local/lib/python3.12/site-packages/airflow/task/task_runner/standard_task_runner.py", line 117, in _start_by_fork
    ret = args.func(args, dag=self.dag)
          ^^^^^^^^^^^^^^^^^^^^^^^^^^^^^
  File "/home/airflow/.local/lib/python3.12/site-packages/airflow/cli/cli_config.py", line 49, in command
    return func(*args, **kwargs)
           ^^^^^^^^^^^^^^^^^^^^^
  File "/home/airflow/.local/lib/python3.12/site-packages/airflow/utils/cli.py", line 115, in wrapper
    return f(*args, **kwargs)
           ^^^^^^^^^^^^^^^^^^
  File "/home/airflow/.local/lib/python3.12/site-packages/airflow/cli/commands/task_command.py", line 483, in task_run
    task_return_code = _run_task_by_selected_method(args, _dag, ti)
                       ^^^^^^^^^^^^^^^^^^^^^^^^^^^^^^^^^^^^^^^^^^^^
  File "/home/airflow/.local/lib/python3.12/site-packages/airflow/cli/commands/task_command.py", line 256, in _run_task_by_selected_method
    return _run_raw_task(args, ti)
           ^^^^^^^^^^^^^^^^^^^^^^^
  File "/home/airflow/.local/lib/python3.12/site-packages/airflow/cli/commands/task_command.py", line 341, in _run_raw_task
    return ti._run_raw_task(
           ^^^^^^^^^^^^^^^^^
  File "/home/airflow/.local/lib/python3.12/site-packages/airflow/utils/session.py", line 97, in wrapper
    return func(*args, session=session, **kwargs)
           ^^^^^^^^^^^^^^^^^^^^^^^^^^^^^^^^^^^^^^
  File "/home/airflow/.local/lib/python3.12/site-packages/airflow/models/taskinstance.py", line 3004, in _run_raw_task
    return _run_raw_task(
           ^^^^^^^^^^^^^^
  File "/home/airflow/.local/lib/python3.12/site-packages/airflow/models/taskinstance.py", line 273, in _run_raw_task
    TaskInstance._execute_task_with_callbacks(
  File "/home/airflow/.local/lib/python3.12/site-packages/airflow/models/taskinstance.py", line 3158, in _execute_task_with_callbacks
    result = self._execute_task(context, task_orig)
             ^^^^^^^^^^^^^^^^^^^^^^^^^^^^^^^^^^^^^^
  File "/home/airflow/.local/lib/python3.12/site-packages/airflow/models/taskinstance.py", line 3182, in _execute_task
    return _execute_task(self, context, task_orig)
           ^^^^^^^^^^^^^^^^^^^^^^^^^^^^^^^^^^^^^^^
  File "/home/airflow/.local/lib/python3.12/site-packages/airflow/models/taskinstance.py", line 767, in _execute_task
    result = _execute_callable(context=context, **execute_callable_kwargs)
             ^^^^^^^^^^^^^^^^^^^^^^^^^^^^^^^^^^^^^^^^^^^^^^^^^^^^^^^^^^^^^
  File "/home/airflow/.local/lib/python3.12/site-packages/airflow/models/taskinstance.py", line 733, in _execute_callable
    return ExecutionCallableRunner(
           ^^^^^^^^^^^^^^^^^^^^^^^^
  File "/home/airflow/.local/lib/python3.12/site-packages/airflow/utils/operator_helpers.py", line 252, in run
    return self.func(*args, **kwargs)
           ^^^^^^^^^^^^^^^^^^^^^^^^^^
  File "/home/airflow/.local/lib/python3.12/site-packages/airflow/models/baseoperator.py", line 406, in wrapper
    return func(self, *args, **kwargs)
           ^^^^^^^^^^^^^^^^^^^^^^^^^^^
  File "/home/airflow/.local/lib/python3.12/site-packages/airflow/operators/python.py", line 238, in execute
    return_value = self.execute_callable()
                   ^^^^^^^^^^^^^^^^^^^^^^^
  File "/home/airflow/.local/lib/python3.12/site-packages/airflow/operators/python.py", line 256, in execute_callable
    return runner.run(*self.op_args, **self.op_kwargs)
           ^^^^^^^^^^^^^^^^^^^^^^^^^^^^^^^^^^^^^^^^^^^
  File "/home/airflow/.local/lib/python3.12/site-packages/airflow/utils/operator_helpers.py", line 252, in run
    return self.func(*args, **kwargs)
           ^^^^^^^^^^^^^^^^^^^^^^^^^^
  File "/opt/airflow/functions_etl/load_data.py", line 124, in load_data_to_Redshift
    df = load_data(file)  # Ensure load_data has error handling
         ^^^^^^^^^^^^^^^
  File "/opt/airflow/functions_etl/load_data.py", line 68, in load_data
    raise RuntimeError(f"Error reading file: {e}")
RuntimeError: Error reading file: Bad magic number for central directory
[2024-10-30T11:59:41.574+0000] {local_task_job_runner.py:266} INFO - Task exited with return code 1
[2024-10-30T11:59:41.629+0000] {taskinstance.py:3900} INFO - 0 downstream tasks scheduled from follow-on schedule check
[2024-10-30T11:59:41.637+0000] {local_task_job_runner.py:245} INFO - ::endgroup::
[2024-10-30T12:49:28.261+0000] {local_task_job_runner.py:123} INFO - ::group::Pre task execution logs
[2024-10-30T12:49:28.334+0000] {taskinstance.py:2612} INFO - Dependencies all met for dep_context=non-requeueable deps ti=<TaskInstance: etl_update_stock_ferrimac.load_data_into_Redshif scheduled__2024-10-28T22:00:00+00:00 [queued]>
[2024-10-30T12:49:28.390+0000] {taskinstance.py:2612} INFO - Dependencies all met for dep_context=requeueable deps ti=<TaskInstance: etl_update_stock_ferrimac.load_data_into_Redshif scheduled__2024-10-28T22:00:00+00:00 [queued]>
[2024-10-30T12:49:28.396+0000] {taskinstance.py:2865} INFO - Starting attempt 1 of 2
[2024-10-30T12:49:28.447+0000] {taskinstance.py:2888} INFO - Executing <Task(PythonOperator): load_data_into_Redshif> on 2024-10-28 22:00:00+00:00
[2024-10-30T12:49:28.476+0000] {warnings.py:112} WARNING - /home/***/.local/lib/python3.12/site-packages/***/task/task_runner/standard_task_runner.py:70: DeprecationWarning: This process (pid=175) is multi-threaded, use of fork() may lead to deadlocks in the child.
  pid = os.fork()

[2024-10-30T12:49:28.482+0000] {standard_task_runner.py:72} INFO - Started process 187 to run task
[2024-10-30T12:49:28.480+0000] {standard_task_runner.py:104} INFO - Running: ['***', 'tasks', 'run', 'etl_update_stock_ferrimac', 'load_data_into_Redshif', 'scheduled__2024-10-28T22:00:00+00:00', '--job-id', '14', '--raw', '--subdir', 'DAGS_FOLDER/object_dag.py', '--cfg-path', '/tmp/tmpqsr2ahwg']
[2024-10-30T12:49:28.490+0000] {standard_task_runner.py:105} INFO - Job 14: Subtask load_data_into_Redshif
[2024-10-30T12:49:28.681+0000] {task_command.py:467} INFO - Running <TaskInstance: etl_update_stock_ferrimac.load_data_into_Redshif scheduled__2024-10-28T22:00:00+00:00 [running]> on host 1e26175021c2
[2024-10-30T12:49:28.947+0000] {taskinstance.py:3131} INFO - Exporting env vars: AIRFLOW_CTX_DAG_OWNER='***' AIRFLOW_CTX_DAG_ID='etl_update_stock_ferrimac' AIRFLOW_CTX_TASK_ID='load_data_into_Redshif' AIRFLOW_CTX_EXECUTION_DATE='2024-10-28T22:00:00+00:00' AIRFLOW_CTX_TRY_NUMBER='1' AIRFLOW_CTX_DAG_RUN_ID='scheduled__2024-10-28T22:00:00+00:00'
[2024-10-30T12:49:28.950+0000] {taskinstance.py:731} INFO - ::endgroup::
[2024-10-30T12:49:32.266+0000] {load_data.py:116} INFO - Connection to Redshift successful.
[2024-10-30T12:49:32.596+0000] {load_data.py:119} INFO - Update from Redshift: 2024-10-30
[2024-10-30T12:49:33.385+0000] {taskinstance.py:3310} ERROR - Task failed with exception
Traceback (most recent call last):
  File "/opt/airflow/functions_etl/load_data.py", line 54, in load_data
    df = pd.read_excel(file_path, engine='openpyxl')
         ^^^^^^^^^^^^^^^^^^^^^^^^^^^^^^^^^^^^^^^^^^^
  File "/home/airflow/.local/lib/python3.12/site-packages/pandas/io/excel/_base.py", line 504, in read_excel
    io = ExcelFile(
         ^^^^^^^^^^
  File "/home/airflow/.local/lib/python3.12/site-packages/pandas/io/excel/_base.py", line 1580, in __init__
    self._reader = self._engines[engine](
                   ^^^^^^^^^^^^^^^^^^^^^^
  File "/home/airflow/.local/lib/python3.12/site-packages/pandas/io/excel/_openpyxl.py", line 553, in __init__
    super().__init__(
  File "/home/airflow/.local/lib/python3.12/site-packages/pandas/io/excel/_base.py", line 582, in __init__
    self.book = self.load_workbook(self.handles.handle, engine_kwargs)
                ^^^^^^^^^^^^^^^^^^^^^^^^^^^^^^^^^^^^^^^^^^^^^^^^^^^^^^
  File "/home/airflow/.local/lib/python3.12/site-packages/pandas/io/excel/_openpyxl.py", line 570, in load_workbook
    return load_workbook(
           ^^^^^^^^^^^^^^
  File "/home/airflow/.local/lib/python3.12/site-packages/openpyxl/reader/excel.py", line 315, in load_workbook
    reader = ExcelReader(filename, read_only, keep_vba,
             ^^^^^^^^^^^^^^^^^^^^^^^^^^^^^^^^^^^^^^^^^^
  File "/home/airflow/.local/lib/python3.12/site-packages/openpyxl/reader/excel.py", line 124, in __init__
    self.archive = _validate_archive(fn)
                   ^^^^^^^^^^^^^^^^^^^^^
  File "/home/airflow/.local/lib/python3.12/site-packages/openpyxl/reader/excel.py", line 96, in _validate_archive
    archive = ZipFile(filename, 'r')
              ^^^^^^^^^^^^^^^^^^^^^^
  File "/usr/local/lib/python3.12/zipfile/__init__.py", line 1349, in __init__
    self._RealGetContents()
  File "/usr/local/lib/python3.12/zipfile/__init__.py", line 1446, in _RealGetContents
    raise BadZipFile("Bad magic number for central directory")
zipfile.BadZipFile: Bad magic number for central directory

During handling of the above exception, another exception occurred:

Traceback (most recent call last):
  File "/home/airflow/.local/lib/python3.12/site-packages/airflow/models/taskinstance.py", line 767, in _execute_task
    result = _execute_callable(context=context, **execute_callable_kwargs)
             ^^^^^^^^^^^^^^^^^^^^^^^^^^^^^^^^^^^^^^^^^^^^^^^^^^^^^^^^^^^^^
  File "/home/airflow/.local/lib/python3.12/site-packages/airflow/models/taskinstance.py", line 733, in _execute_callable
    return ExecutionCallableRunner(
           ^^^^^^^^^^^^^^^^^^^^^^^^
  File "/home/airflow/.local/lib/python3.12/site-packages/airflow/utils/operator_helpers.py", line 252, in run
    return self.func(*args, **kwargs)
           ^^^^^^^^^^^^^^^^^^^^^^^^^^
  File "/home/airflow/.local/lib/python3.12/site-packages/airflow/models/baseoperator.py", line 406, in wrapper
    return func(self, *args, **kwargs)
           ^^^^^^^^^^^^^^^^^^^^^^^^^^^
  File "/home/airflow/.local/lib/python3.12/site-packages/airflow/operators/python.py", line 238, in execute
    return_value = self.execute_callable()
                   ^^^^^^^^^^^^^^^^^^^^^^^
  File "/home/airflow/.local/lib/python3.12/site-packages/airflow/operators/python.py", line 256, in execute_callable
    return runner.run(*self.op_args, **self.op_kwargs)
           ^^^^^^^^^^^^^^^^^^^^^^^^^^^^^^^^^^^^^^^^^^^
  File "/home/airflow/.local/lib/python3.12/site-packages/airflow/utils/operator_helpers.py", line 252, in run
    return self.func(*args, **kwargs)
           ^^^^^^^^^^^^^^^^^^^^^^^^^^
  File "/opt/airflow/functions_etl/load_data.py", line 124, in load_data_to_Redshift
    df = load_data(file)  # Ensure load_data has error handling
         ^^^^^^^^^^^^^^^
  File "/opt/airflow/functions_etl/load_data.py", line 68, in load_data
    raise RuntimeError(f"Error reading file: {e}")
RuntimeError: Error reading file: Bad magic number for central directory
[2024-10-30T12:49:33.464+0000] {taskinstance.py:1225} INFO - Marking task as UP_FOR_RETRY. dag_id=etl_update_stock_ferrimac, task_id=load_data_into_Redshif, run_id=scheduled__2024-10-28T22:00:00+00:00, execution_date=20241028T220000, start_date=20241030T124928, end_date=20241030T124933
[2024-10-30T12:49:33.583+0000] {taskinstance.py:340} INFO - ::group::Post task execution logs
[2024-10-30T12:49:33.600+0000] {standard_task_runner.py:124} ERROR - Failed to execute job 14 for task load_data_into_Redshif (Error reading file: Bad magic number for central directory; 187)
Traceback (most recent call last):
  File "/opt/airflow/functions_etl/load_data.py", line 54, in load_data
    df = pd.read_excel(file_path, engine='openpyxl')
         ^^^^^^^^^^^^^^^^^^^^^^^^^^^^^^^^^^^^^^^^^^^
  File "/home/airflow/.local/lib/python3.12/site-packages/pandas/io/excel/_base.py", line 504, in read_excel
    io = ExcelFile(
         ^^^^^^^^^^
  File "/home/airflow/.local/lib/python3.12/site-packages/pandas/io/excel/_base.py", line 1580, in __init__
    self._reader = self._engines[engine](
                   ^^^^^^^^^^^^^^^^^^^^^^
  File "/home/airflow/.local/lib/python3.12/site-packages/pandas/io/excel/_openpyxl.py", line 553, in __init__
    super().__init__(
  File "/home/airflow/.local/lib/python3.12/site-packages/pandas/io/excel/_base.py", line 582, in __init__
    self.book = self.load_workbook(self.handles.handle, engine_kwargs)
                ^^^^^^^^^^^^^^^^^^^^^^^^^^^^^^^^^^^^^^^^^^^^^^^^^^^^^^
  File "/home/airflow/.local/lib/python3.12/site-packages/pandas/io/excel/_openpyxl.py", line 570, in load_workbook
    return load_workbook(
           ^^^^^^^^^^^^^^
  File "/home/airflow/.local/lib/python3.12/site-packages/openpyxl/reader/excel.py", line 315, in load_workbook
    reader = ExcelReader(filename, read_only, keep_vba,
             ^^^^^^^^^^^^^^^^^^^^^^^^^^^^^^^^^^^^^^^^^^
  File "/home/airflow/.local/lib/python3.12/site-packages/openpyxl/reader/excel.py", line 124, in __init__
    self.archive = _validate_archive(fn)
                   ^^^^^^^^^^^^^^^^^^^^^
  File "/home/airflow/.local/lib/python3.12/site-packages/openpyxl/reader/excel.py", line 96, in _validate_archive
    archive = ZipFile(filename, 'r')
              ^^^^^^^^^^^^^^^^^^^^^^
  File "/usr/local/lib/python3.12/zipfile/__init__.py", line 1349, in __init__
    self._RealGetContents()
  File "/usr/local/lib/python3.12/zipfile/__init__.py", line 1446, in _RealGetContents
    raise BadZipFile("Bad magic number for central directory")
zipfile.BadZipFile: Bad magic number for central directory

During handling of the above exception, another exception occurred:

Traceback (most recent call last):
  File "/home/airflow/.local/lib/python3.12/site-packages/airflow/task/task_runner/standard_task_runner.py", line 117, in _start_by_fork
    ret = args.func(args, dag=self.dag)
          ^^^^^^^^^^^^^^^^^^^^^^^^^^^^^
  File "/home/airflow/.local/lib/python3.12/site-packages/airflow/cli/cli_config.py", line 49, in command
    return func(*args, **kwargs)
           ^^^^^^^^^^^^^^^^^^^^^
  File "/home/airflow/.local/lib/python3.12/site-packages/airflow/utils/cli.py", line 115, in wrapper
    return f(*args, **kwargs)
           ^^^^^^^^^^^^^^^^^^
  File "/home/airflow/.local/lib/python3.12/site-packages/airflow/cli/commands/task_command.py", line 483, in task_run
    task_return_code = _run_task_by_selected_method(args, _dag, ti)
                       ^^^^^^^^^^^^^^^^^^^^^^^^^^^^^^^^^^^^^^^^^^^^
  File "/home/airflow/.local/lib/python3.12/site-packages/airflow/cli/commands/task_command.py", line 256, in _run_task_by_selected_method
    return _run_raw_task(args, ti)
           ^^^^^^^^^^^^^^^^^^^^^^^
  File "/home/airflow/.local/lib/python3.12/site-packages/airflow/cli/commands/task_command.py", line 341, in _run_raw_task
    return ti._run_raw_task(
           ^^^^^^^^^^^^^^^^^
  File "/home/airflow/.local/lib/python3.12/site-packages/airflow/utils/session.py", line 97, in wrapper
    return func(*args, session=session, **kwargs)
           ^^^^^^^^^^^^^^^^^^^^^^^^^^^^^^^^^^^^^^
  File "/home/airflow/.local/lib/python3.12/site-packages/airflow/models/taskinstance.py", line 3004, in _run_raw_task
    return _run_raw_task(
           ^^^^^^^^^^^^^^
  File "/home/airflow/.local/lib/python3.12/site-packages/airflow/models/taskinstance.py", line 273, in _run_raw_task
    TaskInstance._execute_task_with_callbacks(
  File "/home/airflow/.local/lib/python3.12/site-packages/airflow/models/taskinstance.py", line 3158, in _execute_task_with_callbacks
    result = self._execute_task(context, task_orig)
             ^^^^^^^^^^^^^^^^^^^^^^^^^^^^^^^^^^^^^^
  File "/home/airflow/.local/lib/python3.12/site-packages/airflow/models/taskinstance.py", line 3182, in _execute_task
    return _execute_task(self, context, task_orig)
           ^^^^^^^^^^^^^^^^^^^^^^^^^^^^^^^^^^^^^^^
  File "/home/airflow/.local/lib/python3.12/site-packages/airflow/models/taskinstance.py", line 767, in _execute_task
    result = _execute_callable(context=context, **execute_callable_kwargs)
             ^^^^^^^^^^^^^^^^^^^^^^^^^^^^^^^^^^^^^^^^^^^^^^^^^^^^^^^^^^^^^
  File "/home/airflow/.local/lib/python3.12/site-packages/airflow/models/taskinstance.py", line 733, in _execute_callable
    return ExecutionCallableRunner(
           ^^^^^^^^^^^^^^^^^^^^^^^^
  File "/home/airflow/.local/lib/python3.12/site-packages/airflow/utils/operator_helpers.py", line 252, in run
    return self.func(*args, **kwargs)
           ^^^^^^^^^^^^^^^^^^^^^^^^^^
  File "/home/airflow/.local/lib/python3.12/site-packages/airflow/models/baseoperator.py", line 406, in wrapper
    return func(self, *args, **kwargs)
           ^^^^^^^^^^^^^^^^^^^^^^^^^^^
  File "/home/airflow/.local/lib/python3.12/site-packages/airflow/operators/python.py", line 238, in execute
    return_value = self.execute_callable()
                   ^^^^^^^^^^^^^^^^^^^^^^^
  File "/home/airflow/.local/lib/python3.12/site-packages/airflow/operators/python.py", line 256, in execute_callable
    return runner.run(*self.op_args, **self.op_kwargs)
           ^^^^^^^^^^^^^^^^^^^^^^^^^^^^^^^^^^^^^^^^^^^
  File "/home/airflow/.local/lib/python3.12/site-packages/airflow/utils/operator_helpers.py", line 252, in run
    return self.func(*args, **kwargs)
           ^^^^^^^^^^^^^^^^^^^^^^^^^^
  File "/opt/airflow/functions_etl/load_data.py", line 124, in load_data_to_Redshift
    df = load_data(file)  # Ensure load_data has error handling
         ^^^^^^^^^^^^^^^
  File "/opt/airflow/functions_etl/load_data.py", line 68, in load_data
    raise RuntimeError(f"Error reading file: {e}")
RuntimeError: Error reading file: Bad magic number for central directory
[2024-10-30T12:49:33.899+0000] {local_task_job_runner.py:266} INFO - Task exited with return code 1
[2024-10-30T12:49:34.103+0000] {taskinstance.py:3900} INFO - 0 downstream tasks scheduled from follow-on schedule check
[2024-10-30T12:49:34.182+0000] {local_task_job_runner.py:245} INFO - ::endgroup::
[2024-10-30T16:49:51.542+0000] {local_task_job_runner.py:123} INFO - ::group::Pre task execution logs
[2024-10-30T16:49:51.575+0000] {taskinstance.py:2612} INFO - Dependencies all met for dep_context=non-requeueable deps ti=<TaskInstance: etl_update_stock_ferrimac.load_data_into_Redshif scheduled__2024-10-28T22:00:00+00:00 [queued]>
[2024-10-30T16:49:51.591+0000] {taskinstance.py:2612} INFO - Dependencies all met for dep_context=requeueable deps ti=<TaskInstance: etl_update_stock_ferrimac.load_data_into_Redshif scheduled__2024-10-28T22:00:00+00:00 [queued]>
[2024-10-30T16:49:51.592+0000] {taskinstance.py:2865} INFO - Starting attempt 1 of 2
[2024-10-30T16:49:51.622+0000] {taskinstance.py:2888} INFO - Executing <Task(PythonOperator): load_data_into_Redshif> on 2024-10-28 22:00:00+00:00
[2024-10-30T16:49:51.634+0000] {warnings.py:112} WARNING - /home/***/.local/lib/python3.12/site-packages/***/task/task_runner/standard_task_runner.py:70: DeprecationWarning: This process (pid=217) is multi-threaded, use of fork() may lead to deadlocks in the child.
  pid = os.fork()

[2024-10-30T16:49:51.637+0000] {standard_task_runner.py:72} INFO - Started process 221 to run task
[2024-10-30T16:49:51.640+0000] {standard_task_runner.py:104} INFO - Running: ['***', 'tasks', 'run', 'etl_update_stock_ferrimac', 'load_data_into_Redshif', 'scheduled__2024-10-28T22:00:00+00:00', '--job-id', '16', '--raw', '--subdir', 'DAGS_FOLDER/object_dag.py', '--cfg-path', '/tmp/tmpcv_q80b2']
[2024-10-30T16:49:51.645+0000] {standard_task_runner.py:105} INFO - Job 16: Subtask load_data_into_Redshif
[2024-10-30T16:49:51.734+0000] {task_command.py:467} INFO - Running <TaskInstance: etl_update_stock_ferrimac.load_data_into_Redshif scheduled__2024-10-28T22:00:00+00:00 [running]> on host b789ae629a43
[2024-10-30T16:49:51.882+0000] {taskinstance.py:3131} INFO - Exporting env vars: AIRFLOW_CTX_DAG_OWNER='***' AIRFLOW_CTX_DAG_ID='etl_update_stock_ferrimac' AIRFLOW_CTX_TASK_ID='load_data_into_Redshif' AIRFLOW_CTX_EXECUTION_DATE='2024-10-28T22:00:00+00:00' AIRFLOW_CTX_TRY_NUMBER='1' AIRFLOW_CTX_DAG_RUN_ID='scheduled__2024-10-28T22:00:00+00:00'
[2024-10-30T16:49:51.886+0000] {taskinstance.py:731} INFO - ::endgroup::
[2024-10-30T16:49:54.856+0000] {load_data.py:116} INFO - Connection to Redshift successful.
[2024-10-30T16:49:55.178+0000] {load_data.py:119} INFO - Update from Redshift: 2024-10-30
[2024-10-30T16:49:55.342+0000] {taskinstance.py:3310} ERROR - Task failed with exception
Traceback (most recent call last):
  File "/home/airflow/.local/lib/python3.12/site-packages/airflow/models/taskinstance.py", line 767, in _execute_task
    result = _execute_callable(context=context, **execute_callable_kwargs)
             ^^^^^^^^^^^^^^^^^^^^^^^^^^^^^^^^^^^^^^^^^^^^^^^^^^^^^^^^^^^^^
  File "/home/airflow/.local/lib/python3.12/site-packages/airflow/models/taskinstance.py", line 733, in _execute_callable
    return ExecutionCallableRunner(
           ^^^^^^^^^^^^^^^^^^^^^^^^
  File "/home/airflow/.local/lib/python3.12/site-packages/airflow/utils/operator_helpers.py", line 252, in run
    return self.func(*args, **kwargs)
           ^^^^^^^^^^^^^^^^^^^^^^^^^^
  File "/home/airflow/.local/lib/python3.12/site-packages/airflow/models/baseoperator.py", line 406, in wrapper
    return func(self, *args, **kwargs)
           ^^^^^^^^^^^^^^^^^^^^^^^^^^^
  File "/home/airflow/.local/lib/python3.12/site-packages/airflow/operators/python.py", line 238, in execute
    return_value = self.execute_callable()
                   ^^^^^^^^^^^^^^^^^^^^^^^
  File "/home/airflow/.local/lib/python3.12/site-packages/airflow/operators/python.py", line 256, in execute_callable
    return runner.run(*self.op_args, **self.op_kwargs)
           ^^^^^^^^^^^^^^^^^^^^^^^^^^^^^^^^^^^^^^^^^^^
  File "/home/airflow/.local/lib/python3.12/site-packages/airflow/utils/operator_helpers.py", line 252, in run
    return self.func(*args, **kwargs)
           ^^^^^^^^^^^^^^^^^^^^^^^^^^
  File "/opt/airflow/functions_etl/load_data.py", line 124, in load_data_to_Redshift
    df = load_data(file)
       ^^^^^^^^^^^^^^^
  File "/opt/airflow/functions_etl/load_data.py", line 37, in load_data
    raise FileNotFoundError(f"Error: File '{file_path}' not found.")
FileNotFoundError: Error: File 'base_datos/inventario/monetized_stock.xlsx' not found.
[2024-10-30T16:49:55.380+0000] {taskinstance.py:1225} INFO - Marking task as UP_FOR_RETRY. dag_id=etl_update_stock_ferrimac, task_id=load_data_into_Redshif, run_id=scheduled__2024-10-28T22:00:00+00:00, execution_date=20241028T220000, start_date=20241030T164951, end_date=20241030T164955
[2024-10-30T16:49:55.410+0000] {taskinstance.py:340} INFO - ::group::Post task execution logs
[2024-10-30T16:49:55.411+0000] {standard_task_runner.py:124} ERROR - Failed to execute job 16 for task load_data_into_Redshif (Error: File 'base_datos/inventario/monetized_stock.xlsx' not found.; 221)
Traceback (most recent call last):
  File "/home/airflow/.local/lib/python3.12/site-packages/airflow/task/task_runner/standard_task_runner.py", line 117, in _start_by_fork
    ret = args.func(args, dag=self.dag)
          ^^^^^^^^^^^^^^^^^^^^^^^^^^^^^
  File "/home/airflow/.local/lib/python3.12/site-packages/airflow/cli/cli_config.py", line 49, in command
    return func(*args, **kwargs)
           ^^^^^^^^^^^^^^^^^^^^^
  File "/home/airflow/.local/lib/python3.12/site-packages/airflow/utils/cli.py", line 115, in wrapper
    return f(*args, **kwargs)
           ^^^^^^^^^^^^^^^^^^
  File "/home/airflow/.local/lib/python3.12/site-packages/airflow/cli/commands/task_command.py", line 483, in task_run
    task_return_code = _run_task_by_selected_method(args, _dag, ti)
                       ^^^^^^^^^^^^^^^^^^^^^^^^^^^^^^^^^^^^^^^^^^^^
  File "/home/airflow/.local/lib/python3.12/site-packages/airflow/cli/commands/task_command.py", line 256, in _run_task_by_selected_method
    return _run_raw_task(args, ti)
           ^^^^^^^^^^^^^^^^^^^^^^^
  File "/home/airflow/.local/lib/python3.12/site-packages/airflow/cli/commands/task_command.py", line 341, in _run_raw_task
    return ti._run_raw_task(
           ^^^^^^^^^^^^^^^^^
  File "/home/airflow/.local/lib/python3.12/site-packages/airflow/utils/session.py", line 97, in wrapper
    return func(*args, session=session, **kwargs)
           ^^^^^^^^^^^^^^^^^^^^^^^^^^^^^^^^^^^^^^
  File "/home/airflow/.local/lib/python3.12/site-packages/airflow/models/taskinstance.py", line 3004, in _run_raw_task
    return _run_raw_task(
           ^^^^^^^^^^^^^^
  File "/home/airflow/.local/lib/python3.12/site-packages/airflow/models/taskinstance.py", line 273, in _run_raw_task
    TaskInstance._execute_task_with_callbacks(
  File "/home/airflow/.local/lib/python3.12/site-packages/airflow/models/taskinstance.py", line 3158, in _execute_task_with_callbacks
    result = self._execute_task(context, task_orig)
             ^^^^^^^^^^^^^^^^^^^^^^^^^^^^^^^^^^^^^^
  File "/home/airflow/.local/lib/python3.12/site-packages/airflow/models/taskinstance.py", line 3182, in _execute_task
    return _execute_task(self, context, task_orig)
           ^^^^^^^^^^^^^^^^^^^^^^^^^^^^^^^^^^^^^^^
  File "/home/airflow/.local/lib/python3.12/site-packages/airflow/models/taskinstance.py", line 767, in _execute_task
    result = _execute_callable(context=context, **execute_callable_kwargs)
             ^^^^^^^^^^^^^^^^^^^^^^^^^^^^^^^^^^^^^^^^^^^^^^^^^^^^^^^^^^^^^
  File "/home/airflow/.local/lib/python3.12/site-packages/airflow/models/taskinstance.py", line 733, in _execute_callable
    return ExecutionCallableRunner(
           ^^^^^^^^^^^^^^^^^^^^^^^^
  File "/home/airflow/.local/lib/python3.12/site-packages/airflow/utils/operator_helpers.py", line 252, in run
    return self.func(*args, **kwargs)
           ^^^^^^^^^^^^^^^^^^^^^^^^^^
  File "/home/airflow/.local/lib/python3.12/site-packages/airflow/models/baseoperator.py", line 406, in wrapper
    return func(self, *args, **kwargs)
           ^^^^^^^^^^^^^^^^^^^^^^^^^^^
  File "/home/airflow/.local/lib/python3.12/site-packages/airflow/operators/python.py", line 238, in execute
    return_value = self.execute_callable()
                   ^^^^^^^^^^^^^^^^^^^^^^^
  File "/home/airflow/.local/lib/python3.12/site-packages/airflow/operators/python.py", line 256, in execute_callable
    return runner.run(*self.op_args, **self.op_kwargs)
           ^^^^^^^^^^^^^^^^^^^^^^^^^^^^^^^^^^^^^^^^^^^
  File "/home/airflow/.local/lib/python3.12/site-packages/airflow/utils/operator_helpers.py", line 252, in run
    return self.func(*args, **kwargs)
           ^^^^^^^^^^^^^^^^^^^^^^^^^^
  File "/opt/airflow/functions_etl/load_data.py", line 124, in load_data_to_Redshift
    df = load_data(file)
       ^^^^^^^^^^^^^^^
  File "/opt/airflow/functions_etl/load_data.py", line 37, in load_data
    raise FileNotFoundError(f"Error: File '{file_path}' not found.")
FileNotFoundError: Error: File 'base_datos/inventario/monetized_stock.xlsx' not found.
[2024-10-30T16:49:55.470+0000] {local_task_job_runner.py:266} INFO - Task exited with return code 1
[2024-10-30T16:49:55.495+0000] {taskinstance.py:3900} INFO - 0 downstream tasks scheduled from follow-on schedule check
[2024-10-30T16:49:55.498+0000] {local_task_job_runner.py:245} INFO - ::endgroup::
